Workbook

Sheet 规则表
A1: 规则参数
A2: 股东资本 | B2: 1000000
A3: 贷款倍数 | B3: 3
A4: 管理费 | B4: 10000 | D4: 使用说明：1.规则表绿色代表表格引用数据，表格公式计算结果会根据绿色区域填入的规则实时更改，白色区域不可更改 2.灰色代表有公式，尽量不要乱动 3.黄色同样有公式，但如有需要可以根据实际情况更改 4.白色和橙色代表需要手动填入的数据 5.注意！！！维护费、折旧、销售收入、激励、工资这些数据仅为参考值，可用于协助做方案，实际操作时需根据实际情况更改 6.如需使用12小时制，需自行修改激励或辞退福利 7.涨薪行为默认下一年年初辞退，不再多给工资，且辞退福利需要自己计算 8.该表格需要使用WPS2019以后的版本或excel365版本打开，否则会出现部分报错情况
A5: 税率 | B5: 0.25
A6: 1季短贷 | B6: 0.03
A7: 4季短贷 | B7: 0.1
A8: 2年长贷 | B8: 0.03
A9: 贴现 | B9: 利率
A10: 0 | B10: 0
A11: 1 | B11: 0.02
A12: 2 | B12: 0.04
A13: 3 | B13: 0.06
A14: 4 | B14: 0.08
A16: 线型名称 | B16: 购买价格（元） | C16: 安装周期（季） | D16: 生产周期（季） | E16: 产量 | F16: 转产周期（季） | G16: 转产价格（元） | H16: 残值（元） | I16: 维修费用（元） | J16: 普通工 | K16: 高级工 | L16: 碳排放量 | M16: 折旧年限 | N16: 普通效率（%） | O16: 高级效率（%） | P16: 8小时总产量 | Q16: 12小时总产量 | R16: 单条线工 资（季） | S16: 单条线生 产费用 | T16: 单条线总激励 | U16: 每次8小时消耗费用 | V16: 每次12小时消耗费用 | W16: 单条线涨薪总费用 | X16: 每次线涨薪费用
A17: 传统线 | B17: 100000 | C17: 0 | D17: 2 | E17: 50 | F17: 0 | G17: 20000 | H17: 10000 | I17: 10000 | J17: 2 | K17: 1 | L17: 0 | M17: 4 | N17: 100 | O17: 100 | P17: =INT(E17*(1+J17*N17/400+K17*O17/100)) -> 125 | Q17: =INT(E17*(1+J17*N17/400+K17*O17/100)*$L$32) -> 150 | R17: =(J17*$L$23+K17*$L$24)*3 -> 9000 | S17: =J17*P17*$M$23+K17*P17*$M$24 -> 12500 | T17: =(N17-$O$23)*$M$27*J17+(O17-$O$24)*$M$27*K17 -> 12000 | U17: =(J17+K17)*$M$27*$M$31 -> 600 | V17: =(J17+K17)*$M$27*$M$32 -> 15000 | W17: =ROUNDUP((N17-$O$23)*$M$28*J17+(O17-$O$24)*$M$28*K17,0) -> 2040 | X17: =ROUNDUP($M$31*$M$28*J17+$M$31*$M$28*K17,0) -> 102
A18: 自动线 | B18: 160000 | C18: 1 | D18: 1 | E18: 35 | F18: 0 | G18: 10000 | H18: 10000 | I18: 10000 | J18: 1 | K18: 1 | L18: 0 | M18: 4 | N18: 100 | O18: 100 | P18: =INT(E18*(1+J18*N18/400+K18*O18/100)) -> 78 | Q18: =INT(E18*(1+J18*N18/400+K18*O18/100)*$L$32) -> 94 | R18: =(J18*$L$23+K18*$L$24)*3 -> 7500 | S18: =J18*P18*$M$23+K18*P18*$M$24 -> 5850 | T18: =(N18-$O$23)*$M$27*J18+(O18-$O$24)*$M$27*K18 -> 8000 | U18: =(J18+K18)*$M$27*$M$31 -> 400 | V18: =(J18+K18)*$M$27*$M$32 -> 10000 | W18: =ROUNDUP((N18-$O$23)*$M$28*J18+(O18-$O$24)*$M$28*K18,0) -> 1360 | X18: =ROUNDUP($M$31*$M$28*J18+$M$31*$M$28*K18,0) -> 68
A19: 智能线 | B19: 250000 | C19: 2 | D19: 1 | E19: 30 | F19: 0 | G19: 0 | H19: 50000 | I19: 10000 | J19: 1 | K19: 2 | L19: 0 | M19: 4 | N19: 100 | O19: 100 | P19: =INT(E19*(1+J19*N19/400+K19*O19/100)) -> 97 | Q19: =INT(E19*(1+J19*N19/400+K19*O19/100)*$L$32) -> 117 | R19: =(J19*$L$23+K19*$L$24)*3 -> 13500 | S19: =J19*P19*$M$23+K19*P19*$M$24 -> 12125 | T19: =(N19-$O$23)*$M$27*J19+(O19-$O$24)*$M$27*K19 -> 12000 | U19: =(J19+K19)*$M$27*$M$31 -> 600 | V19: =(J19+K19)*$M$27*$M$32 -> 15000 | W19: =ROUNDUP((N19-$O$23)*$M$28*J19+(O19-$O$24)*$M$28*K19,0) -> 2040 | X19: =ROUNDUP($M$31*$M$28*J19+$M$31*$M$28*K19,0) -> 102
A22: 产品编号 | B22: 产品成本 | C22: R1 | D22: R2 | E22: R3 | F22: R4 | G22: R5 | H22: 材料总费用 | J22: 名称 | K22: 编码 | L22: 初始期望工资（元） | M22: 计件 | N22: 每季度数量 | O22: 效率（%） | U22: 12小时制
A23: =现金流量表!H54 -> P1 | B23: 1800 | C23: 2 | D23: 2 | E23: 1 | F23: 0 | G23: 0 | H23: =C23*$C$30+D23*$D$30+E23*$E$30+F23*$F$30+G23*$G$30 -> 500 | J23: 初级工 | K23: GR1 | L23: 500 | M23: 25 | N23: 20 | O23: 60 | U23: 单个成本 | V23: 成本利润率
A24: =现金流量表!H55 -> P2 | B24: 3400 | C24: 2 | D24: 3 | E24: 2 | F24: 2 | G24: 0 | H24: =C24*$C$30+D24*$D$30+E24*$E$30+F24*$F$30+G24*$G$30 -> 900 | J24: 高级工 | K24: GR2 | L24: 2000 | M24: 50 | N24: 10 | O24: 60 | S24: 利润 | T24: 4150 | U24: =(V17-U17)/(Q17-P17) -> 576 | V24: =T24/U24 -> 7.2048611
A25: =现金流量表!H56 -> P3 | B25: 5800 | C25: 5 | D25: 3 | E25: 3 | F25: 4 | G25: 0 | H25: =C25*$C$30+D25*$D$30+E25*$E$30+F25*$F$30+G25*$G$30 -> 1500 | U25: =(V18-U18)/(Q18-P18) -> 600 | V25: =T25/U25 -> 0
A26: =现金流量表!H57 -> P4 | B26: 8600 | C26: 6 | D26: 7 | E26: 5 | F26: 5 | H26: =C26*$C$30+D26*$D$30+E26*$E$30+F26*$F$30+G26*$G$30 -> 2300 | J26: 激励名称 | K26: 编码 | L26: 提升效率比例（%） | M26: 每1%需要费用 | U26: =(V19-U19)/(Q19-P19) -> 720 | V26: =T26/U26 -> 0
A27: =现金流量表!H58 -> 0 | B27: 6000 | H27: =C27*$C$30+D27*$D$30+E27*$E$30+F27*$F$30+G27*$G$30 -> 0 | J27: 奖金激励 | K27: JL1 | L27: 100 | M27: =ROUNDUP(10000/L27,0) -> 100
B28: 送货周期 | C28: 1 | D28: 1 | E28: 1 | F28: 2 | G28: 1 | J28: 涨薪激励 | K28: JL2 | L28: 600 | M28: =ROUNDUP(10000/L28,0) -> 17 | R28: =B17+R17+S17+T17+P17*H23 -> 196000 | S28: =R28/P17 -> 1568
B29: 账期 | C29: 0 | D29: 0 | E29: 0 | F29: 0 | G29: 0
B30: 材料价格 | C30: 100 | D30: 100 | E30: 100 | F30: 100 | G30: 0 | J30: 班次名称 | K30: 班次编码 | L30: 产量加成（倍） | M30: 效率损失（%）
J31: 8小时制 | K31: BC1 | L31: 1 | M31: 2 | Q31: 正单与补单利润差
J32: 12小时制 | K32: BC2 | L32: 1.2 | M32: 50
A35: 8小时 | B35: =A17 -> 传统线 | C35: =A18 -> 自动线 | D35: =A19 -> 智能线
A36: =A23 -> P1 | B36: =(H23*$P$17+$S$17+$U$17+$R$17*2)/$P$17 -> 748.8 | C36: =(H23*$P$18+$S$18+$U$18+$R$18)/$P$18 -> 676.28205 | D36: =(H23*$P$19+$S$19+$U$19+$R$19)/$P$19 -> 770.36082
A37: =A24 -> P2 | B37: =(H24*$P$17+$S$17+$U$17+$R$17*2)/$P$17 -> 1148.8 | C37: =(H24*$P$18+$S$18+$U$18+$R$18)/$P$18 -> 1076.2821 | D37: =(H24*$P$19+$S$19+$U$19+$R$19)/$P$19 -> 1170.3608
A38: =A25 -> P3 | B38: =(H25*$P$17+$S$17+$U$17+$R$17*2)/$P$17 -> 1748.8 | C38: =(H25*$P$18+$S$18+$U$18+$R$18)/$P$18 -> 1676.2821 | D38: =(H25*$P$19+$S$19+$U$19+$R$19)/$P$19 -> 1770.3608
A39: =A26 -> P4 | B39: =(H26*$P$17+$S$17+$U$17+$R$17*2)/$P$17 -> 2548.8 | C39: =(H26*$P$18+$S$18+$U$18+$R$18)/$P$18 -> 2476.2821 | D39: =(H26*$P$19+$S$19+$U$19+$R$19)/$P$19 -> 2570.3608
A40: =A27 -> 0 | B40: =(H27*$P$17+$S$17+$U$17+$R$17*2)/$P$17 -> 248.8 | C40: =(H27*$P$18+$S$18+$U$18+$R$18)/$P$18 -> 176.28205 | D40: =(H27*$P$19+$S$19+$U$19+$R$19)/$P$19 -> 270.36082
A43: 12小时 | B43: =B35 -> 传统线 | C43: =C35 -> 自动线 | D43: =D35 -> 智能线
A44: =A36 -> P1 | B44: =($Q$17*H23+$R$17+$S$17+$V$17)/$Q$17 -> 743.33333 | C44: =($Q$18*H23+$R$18+$S$18+$V$18)/$Q$18 -> 748.40426 | D44: =($Q$19*H23+$R$19+$S$19+$V$19)/$Q$19 -> 847.22222 | K44: =18*94 -> 1692
A45: =A37 -> P2 | B45: =($Q$17*H24+$R$17+$S$17+$V$17)/$Q$17 -> 1143.3333 | C45: =($Q$18*H24+$R$18+$S$18+$V$18)/$Q$18 -> 1148.4043 | D45: =($Q$19*H24+$R$19+$S$19+$V$19)/$Q$19 -> 1247.2222
A46: =A38 -> P3 | B46: =($Q$17*H25+$R$17+$S$17+$V$17)/$Q$17 -> 1743.3333 | C46: =($Q$18*H25+$R$18+$S$18+$V$18)/$Q$18 -> 1748.4043 | D46: =($Q$19*H25+$R$19+$S$19+$V$19)/$Q$19 -> 1847.2222
A47: =A39 -> P4 | B47: =($Q$17*H26+$R$17+$S$17+$V$17)/$Q$17 -> 2543.3333 | C47: =($Q$18*H26+$R$18+$S$18+$V$18)/$Q$18 -> 2548.4043 | D47: =($Q$19*H26+$R$19+$S$19+$V$19)/$Q$19 -> 2647.2222
...

Sheet 订单贴现表
C1: 第一年 | G1: 第二年 | K1: 第三年 | O1: 第四年
C2: 第一季 | D2: 第二季 | E2: 第三季 | F2: 第四季 | G2: 第一季 | H2: 第二季 | I2: 第三季 | J2: 第四季 | K2: 第一季 | L2: 第二季 | M2: 第三季 | N2: 第四季 | O2: 第一季 | P2: 第二季 | Q2: 第三季 | R2: 第四季
A3: 需填 | B3: 0期
B4: 1期
B5: 2期
B6: 3期
B7: 4期
A8: 期初 | B8: 已收 | C8: =N(OFFSET(C8,-5,0))+N(OFFSET(C8,-4,-1))+N(OFFSET(C8,-3,-2))+IFERROR(N(OFFSET(C8,-2,-3)),0)+IFERROR(N(OFFSET(C8,-1,-4)),0)+C3 -> 0 | D8: =C9+D3-现金流量表!C50 -> 0 | E8: =D9+E3-现金流量表!D50 -> 0 | F8: =E9+F3-现金流量表!E51 -> 0 | G8: =F9+G3-现金流量表!F51 -> 0 | H8: =G9+H3-现金流量表!O51 -> 0 | I8: =H9+I3-现金流量表!P51 -> 0 | J8: =I9+J3-现金流量表!Q51 -> 0 | K8: =J9+K3-现金流量表!R51 -> 0 | L8: =K9+L3-现金流量表!AA51 -> 0 | M8: =L9+M3-现金流量表!AB51 -> 0 | N8: =M9+N3-现金流量表!AC51 -> 0 | O8: =N9+O3-现金流量表!AD51 -> 0 | P8: =O9+P3-现金流量表!AK51 -> 0 | Q8: =P9+Q3-现金流量表!AL51 -> 0 | R8: =Q9+R3-现金流量表!AM51 -> 0
B9: 1期 | C9: =N(OFFSET(C9,-5,0))+N(OFFSET(C9,-4,-1))+N(OFFSET(C9,-3,-2))+IFERROR(N(OFFSET(C9,-2,-3)),0)+C4 -> 0 | D9: =C10+D4-现金流量表!C51 -> 0 | E9: =D10+E4-现金流量表!D51 -> 0 | F9: =E10+F4-现金流量表!E52 -> 0 | G9: =F10+G4-现金流量表!F52 -> 0 | H9: =G10+H4-现金流量表!O52 -> 0 | I9: =H10+I4-现金流量表!P52 -> 0 | J9: =I10+J4-现金流量表!Q52 -> 0 | K9: =J10+K4-现金流量表!R52 -> 0 | L9: =K10+L4-现金流量表!AA52 -> 0 | M9: =L10+M4-现金流量表!AB52 -> 0 | N9: =M10+N4-现金流量表!AC52 -> 0 | O9: =N10+O4-现金流量表!AD52 -> 0 | P9: =O10+P4-现金流量表!AK52 -> 0 | Q9: =P10+Q4-现金流量表!AL52 -> 0 | R9: =Q10+R4-现金流量表!AM52 -> 0
B10: 2期 | C10: =N(OFFSET(C10,-5,0))+N(OFFSET(C10,-4,-1))+N(OFFSET(C10,-3,-2))+C5 -> 0 | D10: =C11+D5-现金流量表!C52 -> 0 | E10: =D11+E5-现金流量表!D52 -> 0 | F10: =E11+F5-现金流量表!E53 -> 0 | G10: =F11+G5-现金流量表!F53 -> 0 | H10: =G11+H5-现金流量表!O53 -> 0 | I10: =H11+I5-现金流量表!P53 -> 0 | J10: =I11+J5-现金流量表!Q53 -> 0 | K10: =J11+K5-现金流量表!R53 -> 0 | L10: =K11+L5-现金流量表!AA53 -> 0 | M10: =L11+M5-现金流量表!AB53 -> 0 | N10: =M11+N5-现金流量表!AC53 -> 0 | O10: =N11+O5-现金流量表!AD53 -> 0 | P10: =O11+P5-现金流量表!AK53 -> 0 | Q10: =P11+Q5-现金流量表!AL53 -> 0 | R10: =Q11+R5-现金流量表!AM53 -> 0
B11: 3期 | C11: =N(OFFSET(C11,-5,0))+N(OFFSET(C11,-4,-1))+C6 -> 0 | D11: =C12+D6-现金流量表!C53 -> 0 | E11: =E6+D12-现金流量表!D53 -> 0 | F11: =E12+F6-现金流量表!E54 -> 0 | G11: =F12+G6-现金流量表!F54 -> 0 | H11: =G12+H6-现金流量表!O54 -> 0 | I11: =H12+I6-现金流量表!P54 -> 0 | J11: =I12+J6-现金流量表!Q54 -> 0 | K11: =J12+K6-现金流量表!R54 -> 0 | L11: =K12+L6-现金流量表!AA54 -> 0 | M11: =L12+M6-现金流量表!AB54 -> 0 | N11: =M12+N6-现金流量表!AC54 -> 0 | O11: =N12+O6-现金流量表!AD54 -> 0 | P11: =O12+P6-现金流量表!AK54 -> 0 | Q11: =P12+Q6-现金流量表!AL54 -> 0 | R11: =Q12+R6-现金流量表!AM54 -> 0
B12: 4期 | C12: =N(OFFSET(C12,-5,0))+C7 -> 0 | D12: =D7-现金流量表!C54 -> 0 | E12: =E7-现金流量表!D54 -> 0 | F12: =F7 -> 0 | G12: =G7 -> 0 | H12: =H7 -> 0 | I12: =I7 -> 0 | J12: =J7 -> 0 | K12: =K7 -> 0 | L12: =L7 -> 0 | M12: =M7 -> 0 | ... R12: =R7 -> 0
A13: 实时贴现值 | B13: 已收 | C13: =C8-现金流量表!C50 -> 0 | D13: =D8-现金流量表!D50 -> 0 | E13: =E8-现金流量表!E50 -> 0 | F13: =F8-现金流量表!F50 -> 0 | G13: =G8-现金流量表!O50 -> 0 | H13: =H8-现金流量表!P50 -> 0 | I13: =I8-现金流量表!Q50 -> 0 | J13: =J8-现金流量表!R50 -> 0 | K13: =K8-现金流量表!AA50 -> 0 | L13: =L8-现金流量表!AB50 -> 0 | M13: =M8-现金流量表!AC50 -> 0 | N13: =N8-现金流量表!AD50 -> 0 | O13: =O8-现金流量表!AK50 -> 0 | P13: =P8-现金流量表!AL50 -> 0 | Q13: =Q8-现金流量表!AM50 -> 0 | R13: =R8-现金流量表!AN50 -> 0
B14: 1期 | C14: =C9-现金流量表!C51 -> 0 | D14: =D9-现金流量表!D51 -> 0 | E14: =E9-现金流量表!E51 -> 0 | F14: =F9-现金流量表!F51 -> 0 | G14: =G9-现金流量表!O51 -> 0 | H14: =H9-现金流量表!P51 -> 0 | I14: =I9-现金流量表!Q51 -> 0 | J14: =J9-现金流量表!R51 -> 0 | K14: =K9-现金流量表!AA51 -> 0 | L14: =L9-现金流量表!AB51 -> 0 | M14: =M9-现金流量表!AC51 -> 0 | N14: =N9-现金流量表!AD51 -> 0 | O14: =O9-现金流量表!AK51 -> 0 | P14: =P9-现金流量表!AL51 -> 0 | Q14: =Q9-现金流量表!AM51 -> 0 | R14: =R9-现金流量表!AN51 -> 0
B15: 2期 | C15: =C10-现金流量表!C52 -> 0 | D15: =D10-现金流量表!D52 -> 0 | E15: =E10-现金流量表!E52 -> 0 | F15: =F10-现金流量表!F52 -> 0 | G15: =G10-现金流量表!O52 -> 0 | H15: =H10-现金流量表!P52 -> 0 | I15: =I10-现金流量表!Q52 -> 0 | J15: =J10-现金流量表!R52 -> 0 | K15: =K10-现金流量表!AA52 -> 0 | L15: =L10-现金流量表!AB52 -> 0 | M15: =M10-现金流量表!AC52 -> 0 | N15: =N10-现金流量表!AD52 -> 0 | O15: =O10-现金流量表!AK52 -> 0 | P15: =P10-现金流量表!AL52 -> 0 | Q15: =Q10-现金流量表!AM52 -> 0 | R15: =R10-现金流量表!AN52 -> 0
B16: 3期 | C16: =C11-现金流量表!C53 -> 0 | D16: =D11-现金流量表!D53 -> 0 | E16: =E11-现金流量表!E53 -> 0 | F16: =F11-现金流量表!F53 -> 0 | G16: =G11-现金流量表!O53 -> 0 | H16: =H11-现金流量表!P53 -> 0 | I16: =I11-现金流量表!Q53 -> 0 | J16: =J11-现金流量表!R53 -> 0 | K16: =K11-现金流量表!AA53 -> 0 | L16: =L11-现金流量表!AB53 -> 0 | M16: =M11-现金流量表!AC53 -> 0 | N16: =N11-现金流量表!AD53 -> 0 | O16: =O11-现金流量表!AK53 -> 0 | P16: =P11-现金流量表!AL53 -> 0 | Q16: =Q11-现金流量表!AM53 -> 0 | R16: =R11-现金流量表!AN53 -> 0
B17: 4期 | C17: =C12-现金流量表!C54 -> 0 | D17: =D12-现金流量表!D54 -> 0 | E17: =E12-现金流量表!E54 -> 0 | F17: =F12-现金流量表!F54 -> 0 | G17: =G12-现金流量表!O54 -> 0 | H17: =H12-现金流量表!P54 -> 0 | I17: =I12-现金流量表!Q54 -> 0 | J17: =J12-现金流量表!R54 -> 0 | K17: =K12-现金流量表!AA54 -> 0 | L17: =L12-现金流量表!AB54 -> 0 | M17: =M12-现金流量表!AC54 -> 0 | N17: =N12-现金流量表!AD54 -> 0 | O17: =O12-现金流量表!AK54 -> 0 | P17: =P12-现金流量表!AL54 -> 0 | Q17: =Q12-现金流量表!AM54 -> 0 | R17: =R12-现金流量表!AN54 -> 0
A18: 当季贴息 | C18: {=SUMPRODUCT(现金流量表!C50:C54,规则表!$B$10:$B$14)} -> 0 | D18: {=SUMPRODUCT(现金流量表!D50:D54,规则表!$B$10:$B$14)} -> 0 | E18: {=SUMPRODUCT(现金流量表!E50:E54,规则表!$B$10:$B$14)} -> 0 | F18: {=SUMPRODUCT(现金流量表!F50:F54,规则表!$B$10:$B$14)} -> 0 | G18: {=SUMPRODUCT(现金流量表!O50:O54,规则表!$B$10:$B$14)} -> 0 | H18: {=SUMPRODUCT(现金流量表!P50:P54,规则表!$B$10:$B$14)} -> 0 | I18: {=SUMPRODUCT(现金流量表!Q50:Q54,规则表!$B$10:$B$14)} -> 0 | J18: {=SUMPRODUCT(现金流量表!R50:R54,规则表!$B$10:$B$14)} -> 0 | K18: {=SUMPRODUCT(现金流量表!AA50:AA54,规则表!$B$10:$B$14)} -> 0 | L18: {=SUMPRODUCT(现金流量表!AB50:AB54,规则表!$B$10:$B$14)} -> 0 | M18: {=SUMPRODUCT(现金流量表!AC50:AC54,规则表!$B$10:$B$14)} -> 0 | N18: {=SUMPRODUCT(现金流量表!AD50:AD54,规则表!$B$10:$B$14)} -> 0 | O18: {=SUMPRODUCT(现金流量表!AK50:AK54,规则表!$B$10:$B$14)} -> 0 | P18: {=SUMPRODUCT(现金流量表!AL50:AL54,规则表!$B$10:$B$14)} -> 0 | Q18: {=SUMPRODUCT(现金流量表!AM50:AM54,规则表!$B$10:$B$14)} -> 0 | R18: {=SUMPRODUCT(现金流量表!AN50:AN54,规则表!$B$10:$B$14)} -> 0

Sheet 现金流量表
B1: 第一年 | C1: 第一季 | D1: 第二季 | E1: 第三季 | F1: 第四季 | G1: 上年所得税 | N1: 第二年 | O1: 第一季 | P1: 第二季 | Q1: 第三季 | R1: 第四季 | S1: 上年所得税 | T1: =J14 -> 0 | Z1: 第三年 | AA1: 第一季 | AB1: 第二季 | AC1: 第三季 | AD1: 第四季 | AE1: 上年所得税 | AF1: =V14 -> 6445499 | AJ1: 第四年 | AK1: 第一季 | AL1: 第二季 | AM1: 第三季 | AN1: 第四季 | AO1: 上年所得税 | AP1: =AH14 -> 0
B2: 现金盘点 | C2: =规则表!$B$2 -> 1000000 | D2: =C46 -> 2379997 | E2: =D46 -> 2159997 | F2: =E46 -> -966003 | G2: 综合费用表 | I2: 利润表 | N2: 现金盘点 | O2: =F46-T1 -> -1086003 | P2: =O46 -> 11531547 | Q2: =P46 -> 11411547 | R2: =Q46 -> 26570547 | S2: 综合费用表 | U2: 利润表 | Z2: 现金盘点 | AA2: =R46-AF1 -> 20005048 | AB2: =AA46 -> 19050643 | AC2: =AB46 -> 18930643 | AD2: =AC46 -> 18810643 | AE2: 综合费用表 | AG2: 利润表 | AJ2: 现金盘点 | AK2: =AD46-AP1 -> 18690643 | AL2: =AK46 -> 18570643 | AM2: =AL46 -> 18450643 | AN2: =AM46 -> 18330643 | AO2: 综合费用表 | AQ2: 利润表
B3: 损失 | G3: 项目 | H3: 值 | I3: 项目 | J3: 值 | N3: 损失 | S3: 项目 | T3: 值 | U3: 项目 | V3: 值 | Z3: 损失 | AE3: 项目 | AF3: 值 | AG3: 项目 | AH3: 值 | AJ3: 损失 | AO3: 项目 | AP3: 值 | AQ3: 项目 | AR3: 值
B4: 折旧 | C4: =生产建设!I53 -> 0 | D4: =生产建设!J53 -> 0 | E4: =生产建设!K53 -> 0 | F4: =生产建设!L53 -> 0 | G4: 管理费 | H4: =SUM(C15:F15) -> 120000 | I4: 销售收入 | J4: =SUM(C16:F17) -> 0 | K4: 销售收入、直接成本仅为做方案提供参考，如需精确，需自行填入 | N4: 折旧 | O4: =生产建设!M53 -> 0 | P4: =生产建设!N53 -> 0 | Q4: =生产建设!O53 -> 0 | R4: =生产建设!P53 -> 0 | S4: 管理费 | T4: =SUM(O15:R15) -> 120000 | U4: 销售收入 | V4: =SUM(O16:R17)+SUM(O22:R22) -> 36570000 | Z4: 折旧 | AA4: =生产建设!Q53 -> 0 | AB4: =生产建设!R53 -> 0 | AC4: =生产建设!S53 -> 0 | AD4: =生产建设!T53 -> 0 | AE4: 管理费 | AF4: =SUM(AA15:AD15) -> 120000 | AG4: 销售收入 | AJ4: 折旧 | AK4: =生产建设!U53 -> 0 | AL4: =生产建设!V53 -> 0 | AM4: =生产建设!W53 -> 0 | AN4: =生产建设!X53 -> 0 | AO4: 管理费 | AP4: =SUM(AK15:AN15) -> 120000 | AQ4: 销售收入
B5: 现金盘点 | C5: =C2-C3 -> 1000000 | D5: =D2-D3 -> 2379997 | E5: =E2-E3 -> 2159997 | F5: =F2-F3 -> -966003 | G5: 广告费 | H5: =SUM(C43:F43) -> 0 | I5: 直接成本 | J5: =E26+F26+D31+E31+D36+E36 -> 3180000 | N5: 现金盘点 | O5: =O2-O3 -> -1086003 | P5: =P2-P3 -> 11531547 | Q5: =Q2-Q3 -> 11411547 | R5: =R2-R3 -> 26570547 | S5: 广告费 | T5: =SUM(O43:R43) -> 0 | U5: 直接成本 | V5: =SUM(O26:R26)+SUM(O31:Q31)+SUM(O36:Q36)+F31+F36 -> 6360000 | Z5: 现金盘点 | AA5: =AA2-AA3 -> 20005048 | AB5: =AB2-AB3 -> 19050643 | AC5: =AC2-AC3 -> 18930643 | AD5: =AD2-AD3 -> 18810643 | AE5: 广告费 | AF5: =SUM(AA43:AD43) -> 0 | AG5: 直接成本 | AJ5: 现金盘点 | AK5: =AK2-AK3 -> 18690643 | AL5: =AL2-AL3 -> 18570643 | AM5: =AM2-AM3 -> 18450643 | AN5: =AN2-AN3 -> 18330643 | AO5: 广告费 | AP5: =SUM(AK43:AN43) -> 0 | AQ5: 直接成本
B6: 财务总监 | G6: 维修费 | H6: =SUM(C37:F37) -> 0 | I6: 毛利 | J6: =J4-J5 -> -3180000 | N6: 财务总监 | S6: 维修费 | T6: =SUM(O37:R37) -> 0 | U6: 毛利 | V6: =V4-V5 -> 30210000 | Z6: 财务总监 | AE6: 维修费 | AF6: =SUM(AA37:AD37) -> 0 | AG6: 毛利 | AH6: =AH4-AH5 -> 0 | AJ6: 财务总监 | AO6: 维修费 | AP6: =SUM(AK37:AN37) -> 0 | AQ6: 毛利 | AR6: =AR4-AR5 -> 0
B7: 短贷还款 | D7: =C12 -> 0 | E7: =D12 -> 0 | F7: =E12 -> 0 | G7: 转产费 | H7: =SUM(C35:F35) -> 0 | I7: 综合费用 | J7: =H20 -> 816003 | N7: 短贷还款 | O7: =F12+C13 -> 3000000 | P7: =O12+D13 -> 0 | Q7: =P12+E13 -> 0 | R7: =Q12+F13 -> 0 | S7: 转产费 | T7: =SUM(O35:R35) -> 0 | U7: 综合费用 | V7: =T20 -> 132000 | Z7: 短贷还款 | AA7: =R12+O13 -> 758550 | AB7: =AA12+P13 -> 0 | AC7: =AB12+Q13 -> 0 | AD7: =AC12+R13 -> 0 | AE7: 转产费 | AF7: =SUM(AA35:AD35) -> 0 | AG7: 综合费用 | AH7: =AF20 -> 120000 | AJ7: 短贷还款 | AK7: =AD12+AA13 -> 0 | AL7: =AK12+AB13 -> 0 | AM7: =AL12+AC13 -> 0 | AN7: =AM12+AD13 -> 0 | AO7: 转产费 | AP7: =SUM(AK35:AN35) -> 0 | AQ7: 综合费用 | AR7: =AP20 -> 120000
B8: 短贷利息 | D8: =C12*规则表!$B$6 -> 0 | E8: =D12*规则表!$B$6 -> 0 | F8: =E12*规则表!$B$6 -> 0 | G8: 市场开拓 | H8: =SUM(C41:F41) -> 240000 | I8: 折旧前利润 | J8: =J6-J7 -> -3996003 | N8: 短贷利息 | O8: =F12*规则表!$B$6+C13*规则表!$B$7 -> 300000 | P8: =O12*规则表!$B$6+D13*规则表!$B$7 -> 0 | Q8: =P12*规则表!$B$6+E13*规则表!$B$7 -> 0 | R8: =Q12*规则表!$B$6+F13*规则表!$B$7 -> 0 | S8: 市场开拓 | T8: =SUM(O41:R41) -> 0 | U8: 折旧前利润 | V8: =V6-V7 -> 30078000 | Z8: 短贷利息 | AA8: =R12*规则表!$B$6+O13*规则表!$B$7 -> 75855 | AB8: =AA12*规则表!B6+P13*规则表!B7 -> 0 | AC8: =AB12*规则表!B6+Q13*规则表!B7 -> 0 | AD8: =AC12*规则表!B6+R13*规则表!B7 -> 0 | AE8: 市场开拓 | AF8: =SUM(AA41:AD41) -> 0 | AG8: 折旧前利润 | AH8: =AH6-AH7 -> -120000 | AJ8: 短贷利息 | AK8: =AD12*规则表!B6+AA13*规则表!B7 -> 0 | AL8: =AK12*规则表!B6+AB13*规则表!B7 -> 0 | AM8: =AL12*规则表!B6+AC13*规则表!B7 -> 0 | AN8: =AM12*规则表!B6+AD13*规则表!B7 -> 0 | AO8: 市场开拓 | AP8: =SUM(AK41:AN41) -> 0 | AQ8: 折旧前利润 | AR8: =AR6-AR7 -> -120000
B9: 长贷还款 | G9: 产品资质 | H9: =SUM(C40:F40) -> 210000 | I9: 折旧 | J9: =SUM(C4:F4) -> 0 | N9: 长贷还款 | S9: 产品资质 | T9: =SUM(O40:R40) -> 0 | U9: 折旧 | V9: =SUM(O4:R4) -> 0 | Z9: 长贷还款 | AE9: 产品资质 | AF9: =SUM(AA40:AD40) -> 0 | AG9: 折旧 | AH9: =SUM(AA4:AD4) -> 0 | AJ9: 长贷还款 | AO9: 产品资质 | AP9: =SUM(AK40:AN40) -> 0 | AQ9: 折旧 | AR9: =SUM(AK4:AN4) -> 0
B10: 长贷利息 | G10: ISO 认证 | H10: =SUM(C42:F42) -> 240003 | I10: 付息前利润 | J10: =J8-J9 -> -3996003 | N10: 长贷利息 | S10: ISO 认证 | T10: =SUM(O42:R42) -> 0 | U10: 付息前利润 | V10: =V8-V9 -> 30078000 | Z10: 长贷利息 | AE10: ISO 认证 | AF10: =SUM(AA42:AD42) -> 0 | AG10: 付息前利润 | AH10: =AH8-AH9 -> -120000 | AJ10: 长贷利息 | AO10: ISO 认证 | AP10: =SUM(AK42:AN42) -> 0 | AQ10: 付息前利润 | AR10: =AR8-AR9 -> -120000
B11: 贷款额度 | C11: =规则表!$B$2*规则表!$B$3-SUM(C12:C14) -> 0 | D11: =C11+D7+D9-SUM(D12:D14) -> 0 | E11: =D11+E7+E9-SUM(E12:E14) -> 0 | F11: =E11+F7+F9-SUM(F12:F14) -> 0 | G11: 信息费 | H11: =SUM(C20:F20) -> 0 | I11: 财务费用 | J11: =SUM(C8:F8)+SUM(C10:F10)+SUM(C18:F18) -> 0 | N11: 贷款额度 | O11: =J19*规则表!$B$3+O7+O9-SUM(O12:O14)-SUM(C13:F13)-F12-SUM(C14:F14) -> -9746559 | P11: =O11+P7+P9-SUM(P12:P14) -> -9746559 | Q11: =P11+Q7+Q9-SUM(Q12:Q14) -> -9746559 | R11: =Q11+R7+R9-SUM(R12:R14) -> -9746559 | S11: 信息费 | T11: =SUM(O20:R20) -> 0 | U11: 财务费用 | V11: =SUM(O8:R8)+SUM(O10:R10)+SUM(O18:R18) -> 300000 | Z11: 贷款额度 | AA11: =V19*规则表!B3+AA7+AA9-SUM(AA12:AA14)-SUM(O13:R13)-R12-SUM(O14:R14) -> 61009494 | AB11: =AA11+AB7+AB9-SUM(AB12:AB14) -> 61009494 | AC11: =AB11+AC7+AC9-SUM(AC12:AC14) -> 61009494 | AD11: =AC11+AD7+AD9-SUM(AD12:AD14) -> 61009494 | AE11: 信息费 | AF11: =SUM(AA20:AD20) -> 0 | AG11: 财务费用 | AH11: =SUM(AA8:AD8)+SUM(AA10:AD10)+SUM(AA18:AD18) -> 75855 | AJ11: 贷款额度 | AK11: =AH19*规则表!B3+AK7+AK9-SUM(AK12:AK14)-SUM(AA13:AD13)-AD12-SUM(AA14:AD14) -> 60421929 | AL11: =AK11+AL7+AL9-SUM(AL12:AL14) -> 60421929 | AM11: =AL11+AM7+AM9-SUM(AM12:AM14) -> 60421929 | AN11: =AM11+AN7+AN9-SUM(AN12:AN14) -> 60421929 | AO11: 信息费 | AP11: =SUM(AK20:AN20) -> 0 | AQ11: 财务费用 | AR11: =SUM(AK8:AN8)+SUM(AK10:AN10)+SUM(AK18:AN18) -> 0
B12: 1季短贷 | G12: 产品设计 | H12: =SUM(C33:F33) -> 0 | I12: 营业外损失 | K12: 营业外损失用于填写卖原料的成本 | N12: 1季短贷 | S12: 产品设计 | T12: =SUM(O33:R33) -> 0 | U12: 营业外收支 | Z12: 1季短贷 | AE12: 产品设计 | AF12: =SUM(AA33:AD33) -> 0 | AG12: 营业外收支 | AJ12: 1季短贷 | AO12: 产品设计 | AP12: =SUM(AK33:AN33) -> 0 | AQ12: 营业外收支
B13: 4季短贷 | C13: 3000000 | G13: 辞退福利 | H13: =SUM(C28:F28) -> 0 | I13: 税前利润 | J13: =J10-J11-J12 -> -3996003 | N13: 4季短贷 | O13: 758550 | S13: 辞退福利 | T13: =SUM(O28:R28) -> 0 | U13: 税前利润 | V13: =V10-V11-V12 -> 29778000 | Z13: 4季短贷 | AE13: 辞退福利 | AF13: =SUM(AA28:AD28) -> 0 | AG13: 税前利润 | AH13: =AH10-AH11-AH12 -> -195855 | AJ13: 4季短贷 | AO13: 辞退福利 | AP13: =SUM(AK28:AN28) -> 0 | AQ13: 税前利润 | AR13: =AR10-AR11-AR12 -> -120000
B14: 2年长贷 | G14: 培训费 | H14: =SUM(C24:F24) -> 0 | I14: 所得税 | J14: =ROUND(IF(J17>0,IF(J13>0,J13/4,0),IF(J13+J17>0,(J13+J17)/4,0)),0) -> 0 | N14: 2年长贷 | S14: 培训费 | T14: =SUM(O24:R24) -> 0 | U14: 所得税 | V14: =ROUND(IF(V17>0,IF(V13>0,V13/4,0),IF(V13+V17>0,(V13+V17)/4,0)),0) -> 6445499 | Z14: 2年长贷 | AE14: 培训费 | AF14: =SUM(AA24:AD24) -> 0 | AG14: 所得税 | AH14: =ROUND(IF(AH17>0,IF(AH13>0,AH13/4,0),IF(AH13+AH17>0,(AH13+AH17)/4,0)),0) -> 0 | AJ14: 2年长贷 | AO14: 培训费 | AP14: =SUM(AK24:AN24) -> 0 | AQ14: 所得税 | AR14: =ROUND(IF(AR17>0,IF(AR13>0,AR13/4,0),IF(AR13+AR17>0,(AR13+AR17)/4,0)),0) -> 0
B15: 管理费用 | C15: =规则表!$B$4*3 -> 30000 | D15: =规则表!$B$4*3 -> 30000 | E15: =规则表!$B$4*3 -> 30000 | F15: =规则表!$B$4*3 -> 30000 | G15: 激励费 | H15: =SUM(C25:F25) -> 6000 | I15: 净利润 | J15: =J13-J14 -> -3996003 | N15: 管理费用 | O15: =规则表!$B$4*3 -> 30000 | P15: =规则表!$B$4*3 -> 30000 | Q15: =规则表!$B$4*3 -> 30000 | R15: =规则表!$B$4*3 -> 30000 | S15: 激励费 | T15: =SUM(O25:R25) -> 12000 | U15: 净利润 | V15: =V13-V14 -> 23332501 | Z15: 管理费用 | AA15: =规则表!$B$4*3 -> 30000 | AB15: =规则表!$B$4*3 -> 30000 | AC15: =规则表!$B$4*3 -> 30000 | AD15: =规则表!$B$4*3 -> 30000 | AE15: 激励费 | AF15: =SUM(AA25:AD25) -> 0 | AG15: 净利润 | AH15: =AH13-AH14 -> -195855 | AJ15: 管理费用 | AK15: =规则表!$B$4*3 -> 30000 | AL15: =规则表!$B$4*3 -> 30000 | AM15: =规则表!$B$4*3 -> 30000 | AN15: =规则表!$B$4*3 -> 30000 | AO15: 激励费 | AP15: =SUM(AK25:AN25) -> 0 | AQ15: 净利润 | AR15: =AR13-AR14 -> -120000
B16: 应收款到账 | C16: =订单贴现表!C8 -> 0 | D16: =订单贴现表!D8 -> 0 | E16: =订单贴现表!E8 -> 0 | F16: =订单贴现表!F8 -> 0 | G16: 空闲人力费 | H16: =SUM(C27:F27) -> 0 | I16: 股东资本 | J16: =规则表!$B$2 -> 1000000 | N16: 应收款到账 | O16: =订单贴现表!G8 -> 0 | P16: =订单贴现表!H8 -> 0 | Q16: =订单贴现表!I8 -> 0 | R16: =订单贴现表!J8 -> 0 | S16: 空闲人力费 | T16: =SUM(O27:R27) -> 0 | U16: 股东资本 | V16: =规则表!$B$2 -> 1000000 | Z16: 应收款到账 | AA16: =订单贴现表!K8 -> 0 | AB16: =订单贴现表!L8 -> 0 | AC16: =订单贴现表!M8 -> 0 | AD16: =订单贴现表!N8 -> 0 | AE16: 空闲人力费 | AF16: =SUM(AA27:AD27) -> 0 | AG16: 股东资本 | AH16: =规则表!B2 -> 1000000 | AJ16: 应收款到账 | AK16: =订单贴现表!O8 -> 0 | AL16: =订单贴现表!P8 -> 0 | AM16: =订单贴现表!Q8 -> 0 | AN16: =订单贴现表!R8 -> 0 | AO16: 空闲人力费 | AP16: =SUM(AK27:AN27) -> 0 | AQ16: 股东资本 | AR16: =规则表!B2 -> 1000000
B17: 贴现 | E17: {=SUMPRODUCT(材料表!F34:F38,$H$27:$H$31)} -> 0 | F17: {=SUMPRODUCT(材料表!G34:G38,$H$27:$H$31)} -> 0 | G17: 特性研发 | H17: =SUM(C34:F34) -> 0 | I17: 利润留存 | J17: 0 | N17: 贴现 | O17: =材料表!H34*$U$27+材料表!H35*$U$28+材料表!H36*$U$29+材料表!H37*$U$30+材料表!H38*$U$31 -> 18285000 | P17: =材料表!I34*$U$27+材料表!I35*$U$28+材料表!I36*$U$29+材料表!I37*$U$30+材料表!I38*$U$31 -> 0 | Q17: =材料表!J34*$U$27+材料表!J35*$U$28+材料表!J36*$U$29+材料表!J37*$U$30+材料表!J38*$U$31 -> 18285000 | R17: =材料表!K34*$U$27+材料表!K35*$U$28+材料表!K36*$U$29+材料表!K37*$U$30+材料表!K38*$U$31 -> 0 | S17: 特性研发 | T17: =SUM(O34:R34) -> 0 | U17: 利润留存 | V17: =J18 -> -3996003 | Z17: 贴现 | AE17: 特性研发 | AF17: =SUM(AA34:AD34) -> 0 | AG17: 利润留存 | AH17: =V17+V15 -> 19336498 | AJ17: 贴现 | AO17: 特性研发 | AP17: =SUM(AK34:AN34) -> 0 | AQ17: 利润留存 | AR17: =AH17+AH15 -> 19140643
B18: 贴息 | G18: 损失 | H18: =SUM(C3:F3) -> 0 | I18: 年度净利 | J18: =J15 -> -3996003 | N18: 贴息 | S18: 损失 | T18: =SUM(O3:R3)+SUM(O44:R44) -> 0 | U18: 年度净利 | V18: =V15 -> 23332501 | Z18: 贴息 | AE18: 损失 | AF18: =SUM(AA3:AD3) -> 0 | AG18: 年度净利 | AH18: =AH15 -> -195855 | AJ18: 贴息 | AO18: 损失 | AP18: =SUM(AK3:AN3) -> 0 | AQ18: 年度净利 | AR18: =AR15 -> -120000
B19: 应付款 | G19: 违约金 | H19: =SUM(C44:F44) -> 0 | I19: 权益合计 | J19: =SUM(J16:J18) -> -2996003 | N19: 应付款 | S19: 违约金 | T19: =SUM(O44:R44) -> 0 | U19: 权益合计 | V19: =SUM(V16:V18) -> 20336498 | Z19: 应付款 | AE19: 违约金 | AF19: =SUM(AA44:AD44) -> 0 | AG19: 权益合计 | AH19: =SUM(AH16:AH18) -> 20140643 | AJ19: 应付款 | AO19: 违约金 | AP19: =SUM(AK44:AN44) -> 0 | AQ19: 权益合计 | AR19: =SUM(AR16:AR18) -> 20020643
B20: 信息费 | G20: 合计 | H20: =SUM(H4:H19) -> 816003 | N20: g | S20: 合计 | T20: =SUM(T4:T18) -> 132000 | Z20: 信息费 | AE20: 合计 | AF20: =SUM(AF4:AF19) -> 120000 | AJ20: 信息费 | AO20: 合计 | AP20: =SUM(AP4:AP19) -> 120000
B21: 碳中和 | I21: 资金余额 | J21: =O2 -> -1086003 | N21: 碳中和 | Z21: 碳中和 | AJ21: 碳中和
B22: 拆线收入 | C22: {=SUMPRODUCT(生产建设!I64:I66,规则表!$H$17:$H$19)} -> 0 | D22: {=SUMPRODUCT(生产建设!J64:J66,规则表!$H$17:$H$19)} -> 0 | E22: {=SUMPRODUCT(生产建设!K64:K66,规则表!$H$17:$H$19)} -> 0 | F22: {=SUMPRODUCT(生产建设!L64:L66,规则表!$H$17:$H$19)} -> 0 | N22: 拆线收入 | O22: {=SUMPRODUCT(生产建设!M64:M66,规则表!$H$17:$H$19)} -> 0 | P22: {=SUMPRODUCT(生产建设!N64:N66,规则表!$H$17:$H$19)} -> 0 | Q22: {=SUMPRODUCT(生产建设!O64:O66,规则表!$H$17:$H$19)} -> 0 | R22: {=SUMPRODUCT(生产建设!P64:P66,规则表!$H$17:$H$19)} -> 0 | Z22: 拆线收入 | AA22: {=SUMPRODUCT(生产建设!Q64:Q66,规则表!$H$17:$H$19)} -> 0 | AB22: {=SUMPRODUCT(生产建设!R64:R66,规则表!$H$17:$H$19)} -> 0 | AC22: {=SUMPRODUCT(生产建设!S64:S66,规则表!$H$17:$H$19)} -> 0 | AD22: {=SUMPRODUCT(生产建设!T64:T66,规则表!$H$17:$H$19)} -> 0 | AJ22: 拆线费用 | AK22: {=SUMPRODUCT(生产建设!U64:U66,规则表!$H$17:$H$19)} -> 0 | AL22: {=SUMPRODUCT(生产建设!V64:V66,规则表!$H$17:$H$19)} -> 0 | AM22: {=SUMPRODUCT(生产建设!W64:W66,规则表!$H$17:$H$19)} -> 0 | AN22: {=SUMPRODUCT(生产建设!X64:X66,规则表!$H$17:$H$19)} -> 0
B23: 人力总监 | N23: 人力总监 | Z23: 人力总监 | AJ23: 人力总监
B24: 工人培训 | N24: 工人培训 | Z24: 工人培训 | AJ24: 工人培训
B25: 工人激励 | D25: =生产建设!J58 -> 0 | E25: =生产建设!K58 -> 6000 | F25: =生产建设!L58 -> 0 | G25: 产品 | H25: 1.2 | K25: 1.3 | N25: 工人激励 | O25: =生产建设!M58 -> 6000 | P25: =生产建设!N58 -> 0 | Q25: =生产建设!O58 -> 6000 | R25: =生产建设!P58 -> 0 | S25: 产品 | T25: 2.1 | Z25: 工人激励 | AA25: =生产建设!Q58 -> 0 | AB25: =生产建设!R58 -> 0 | AC25: =生产建设!S58 -> 0 | AD25: =生产建设!T58 -> 0 | AJ25: 工人激励 | AK25: =生产建设!U58 -> 0 | AL25: =生产建设!V58 -> 0 | AM25: =生产建设!W58 -> 0 | AN25: =生产建设!X58 -> 0
B26: 工人工资 | C26: =生产建设!I54 -> 0 | D26: =生产建设!J54 -> 90000 | E26: =生产建设!K54 -> 90000 | F26: =生产建设!L54 -> 90000 | H26: 最低价 | I26: 均价 | J26: 最高价 | K26: 最低价 | L26: 均价 | M26: 最高价 | N26: 工人工资 | O26: =生产建设!M54 -> 90000 | P26: =生产建设!N54 -> 90000 | Q26: =生产建设!O54 -> 90000 | R26: =生产建设!P54 -> 90000 | T26: 最低价 | U26: 均价 | V26: 最高价 | Z26: 工人工资 | AA26: =生产建设!Q54 -> 90000 | AB26: =生产建设!R54 -> 90000 | AC26: =生产建设!S54 -> 90000 | AD26: =生产建设!T54 -> 90000 | AJ26: 工人工资 | AK26: =生产建设!U54 -> 90000 | AL26: =生产建设!V54 -> 90000 | AM26: =生产建设!W54 -> 90000 | AN26: =生产建设!X54 -> 90000
B27: 空闲人力费 | G27: =H54 -> P1 | H27: {=INT(MIN(_xlfn._xlws.FILTER(原始订单表!$M:$M,(原始订单表!$A:$A=1)*(原始订单表!$B:$B=2)*(原始订单表!$E:$E=G27),0)))} -> 4800 | I27: {=INT(AVERAGE(_xlfn._xlws.FILTER(原始订单表!$M:$M,(原始订单表!$A:$A=1)*(原始订单表!$B:$B=2)*(原始订单表!$E:$E=G27),0)))} -> 4848 | J27: {=INT(MAX(_xlfn._xlws.FILTER(原始订单表!$M:$M,(原始订单表!$A:$A=1)*(原始订单表!$B:$B=2)*(原始订单表!$E:$E=G27),0)))} -> 4896 | K27: {=INT(MIN(_xlfn._xlws.FILTER(原始订单表!$M:$M,(原始订单表!$A:$A=1)*(原始订单表!$B:$B=3)*(原始订单表!$E:$E=G27),0)))} -> 4032 | L27: {=INT(AVERAGE(_xlfn._xlws.FILTER(原始订单表!$M:$M,(原始订单表!$A:$A=1)*(原始订单表!$B:$B=3)*(原始订单表!$E:$E=G27),0)))} -> 4080 | M27: {=INT(MAX(_xlfn._xlws.FILTER(原始订单表!$M:$M,(原始订单表!$A:$A=1)*(原始订单表!$B:$B=3)*(原始订单表!$E:$E=G27),0)))} -> 4128 | N27: 空闲人力费 | S27: =G27 -> P1 | T27: {=INT(MIN(_xlfn._xlws.FILTER(原始订单表!$M:$M,(原始订单表!$A:$A=2)*(原始订单表!$B:$B=1)*(原始订单表!$E:$E=S27),0)))} -> 4416 | U27: {=INT(AVERAGE(_xlfn._xlws.FILTER(原始订单表!$M:$M,(原始订单表!$A:$A=2)*(原始订单表!$B:$B=1)*(原始订单表!$E:$E=S27),0)))} -> 4909 | V27: {=INT(MAX(_xlfn._xlws.FILTER(原始订单表!$M:$M,(原始订单表!$A:$A=2)*(原始订单表!$B:$B=1)*(原始订单表!$E:$E=S27),0)))} -> 5624 | W27: 2.2 | Z27: 空闲人力费 | AJ27: 空闲人力费
B28: 辞退福利 | G28: =H55 -> P2 | H28: {=INT(MIN(_xlfn._xlws.FILTER(原始订单表!$M:$M,(原始订单表!$A:$A=1)*(原始订单表!$B:$B=2)*(原始订单表!$E:$E=G28),0)))} -> 7938 | I28: {=INT(AVERAGE(_xlfn._xlws.FILTER(原始订单表!$M:$M,(原始订单表!$A:$A=1)*(原始订单表!$B:$B=2)*(原始订单表!$E:$E=G28),0)))} -> 7953 | J28: {=INT(MAX(_xlfn._xlws.FILTER(原始订单表!$M:$M,(原始订单表!$A:$A=1)*(原始订单表!$B:$B=2)*(原始订单表!$E:$E=G28),0)))} -> 7968 | K28: {=INT(MIN(_xlfn._xlws.FILTER(原始订单表!$M:$M,(原始订单表!$A:$A=1)*(原始订单表!$B:$B=3)*(原始订单表!$E:$E=G28),0)))} -> 7200 | L28: {=INT(AVERAGE(_xlfn._xlws.FILTER(原始订单表!$M:$M,(原始订单表!$A:$A=1)*(原始订单表!$B:$B=3)*(原始订单表!$E:$E=G28),0)))} -> 7348 | M28: {=INT(MAX(_xlfn._xlws.FILTER(原始订单表!$M:$M,(原始订单表!$A:$A=1)*(原始订单表!$B:$B=3)*(原始订单表!$E:$E=G28),0)))} -> 7497 | N28: 辞退福利 | S28: =G28 -> P2 | T28: {=INT(MIN(_xlfn._xlws.FILTER(原始订单表!$M:$M,(原始订单表!$A:$A=2)*(原始订单表!$B:$B=1)*(原始订单表!$E:$E=S28),0)))} -> 6816 | U28: {=INT(AVERAGE(_xlfn._xlws.FILTER(原始订单表!M:M,(原始订单表!A:A=2)*(原始订单表!B:B=1)*(原始订单表!E:E=S28),0)))} -> 7622 | V28: {=INT(MAX(_xlfn._xlws.FILTER(原始订单表!$M:$M,(原始订单表!$A:$A=2)*(原始订单表!$B:$B=1)*(原始订单表!$E:$E=S28),0)))} -> 8640 | W28: 最低价 | X28: 均价 | Y28: 最高价 | Z28: 辞退福利 | AJ28: 辞退福利
B29: 预算 | C29: =SUM(C24:C28) -> 0 | D29: =SUM(D24:D28) -> 90000 | E29: =SUM(E24:E28) -> 96000 | F29: =SUM(F24:F28) -> 90000 | G29: =H56 -> P3 | H29: {=INT(MIN(_xlfn._xlws.FILTER(原始订单表!$M:$M,(原始订单表!$A:$A=1)*(原始订单表!$B:$B=2)*(原始订单表!$E:$E=G29),0)))} -> 0 | I29: {=INT(AVERAGE(_xlfn._xlws.FILTER(原始订单表!$M:$M,(原始订单表!$A:$A=1)*(原始订单表!$B:$B=2)*(原始订单表!$E:$E=G29),0)))} -> 0 | J29: {=INT(MAX(_xlfn._xlws.FILTER(原始订单表!$M:$M,(原始订单表!$A:$A=1)*(原始订单表!$B:$B=2)*(原始订单表!$E:$E=G29),0)))} -> 0 | K29: {=INT(MIN(_xlfn._xlws.FILTER(原始订单表!$M:$M,(原始订单表!$A:$A=1)*(原始订单表!$B:$B=3)*(原始订单表!$E:$E=G29),0)))} -> 0 | L29: {=INT(AVERAGE(_xlfn._xlws.FILTER(原始订单表!$M:$M,(原始订单表!$A:$A=1)*(原始订单表!$B:$B=3)*(原始订单表!$E:$E=G29),0)))} -> 0 | M29: {=INT(MAX(_xlfn._xlws.FILTER(原始订单表!$M:$M,(原始订单表!$A:$A=1)*(原始订单表!$B:$B=3)*(原始订单表!$E:$E=G29),0)))} -> 0 | N29: 预算 | O29: =SUM(O24:O28) -> 96000 | P29: =SUM(P24:P28) -> 90000 | Q29: =SUM(Q24:Q28) -> 96000 | R29: =SUM(R24:R28) -> 90000 | S29: =G29 -> P3 | T29: {=INT(MIN(_xlfn._xlws.FILTER(原始订单表!$M:$M,(原始订单表!$A:$A=2)*(原始订单表!$B:$B=1)*(原始订单表!$E:$E=S29),0)))} -> 9792 | U29: {=INT(AVERAGE(_xlfn._xlws.FILTER(原始订单表!$M:$M,(原始订单表!$A:$A=2)*(原始订单表!$B:$B=1)*(原始订单表!$E:$E=S29),0)))} -> 10880 | V29: {=INT(MAX(_xlfn._xlws.FILTER(原始订单表!$M:$M,(原始订单表!$A:$A=2)*(原始订单表!$B:$B=1)*(原始订单表!$E:$E=S29),0)))} -> 12070 | W29: {=INT(MIN(_xlfn._xlws.FILTER(原始订单表!$M:$M,(原始订单表!$A:$A=2)*(原始订单表!$B:$B=2)*(原始订单表!$E:$E=S27),0)))} -> 0 | X29: {=INT(AVERAGE(_xlfn._xlws.FILTER(原始订单表!$M:$M,(原始订单表!$A:$A=2)*(原始订单表!$B:$B=2)*(原始订单表!$E:$E=S27),0)))} -> 0 | Y29: {=INT(MAX(_xlfn._xlws.FILTER(原始订单表!$M:$M,(原始订单表!$A:$A=2)*(原始订单表!$B:$B=2)*(原始订单表!$E:$E=S27),0)))} -> 0 | Z29: 预算 | AA29: =SUM(AA24:AA28) -> 90000 | AB29: =SUM(AB24:AB28) -> 90000 | AC29: =SUM(AC24:AC28) -> 90000 | AD29: =SUM(AD24:AD28) -> 90000 | AJ29: 预算 | AK29: =SUM(AK24:AK28) -> 90000 | AL29: =SUM(AL24:AL28) -> 90000 | AM29: =SUM(AM24:AM28) -> 90000 | AN29: =SUM(AN24:AN28) -> 90000
B30: 生产总监 | G30: =H57 -> P4 | H30: {=INT(MIN(_xlfn._xlws.FILTER(原始订单表!$M:$M,(原始订单表!$A:$A=1)*(原始订单表!$B:$B=2)*(原始订单表!$E:$E=G30),0)))} -> 0 | I30: {=INT(AVERAGE(_xlfn._xlws.FILTER(原始订单表!$M:$M,(原始订单表!$A:$A=1)*(原始订单表!$B:$B=2)*(原始订单表!$E:$E=G30),0)))} -> 0 | J30: {=INT(MAX(_xlfn._xlws.FILTER(原始订单表!$M:$M,(原始订单表!$A:$A=1)*(原始订单表!$B:$B=2)*(原始订单表!$E:$E=G30),0)))} -> 0 | K30: {=INT(MIN(_xlfn._xlws.FILTER(原始订单表!$M:$M,(原始订单表!$A:$A=1)*(原始订单表!$B:$B=3)*(原始订单表!$E:$E=G30),0)))} -> 0 | L30: {=INT(AVERAGE(_xlfn._xlws.FILTER(原始订单表!$M:$M,(原始订单表!$A:$A=1)*(原始订单表!$B:$B=3)*(原始订单表!$E:$E=G30),0)))} -> 0 | M30: {=INT(MAX(_xlfn._xlws.FILTER(原始订单表!$M:$M,(原始订单表!$A:$A=1)*(原始订单表!$B:$B=3)*(原始订单表!$E:$E=G30),0)))} -> 0 | N30: 生产总监 | S30: =G30 -> P4 | T30: {=INT(MIN(_xlfn._xlws.FILTER(原始订单表!$M:$M,(原始订单表!$A:$A=2)*(原始订单表!$B:$B=1)*(原始订单表!$E:$E=S30),0)))} -> 13780 | U30: {=INT(AVERAGE(_xlfn._xlws.FILTER(原始订单表!$M:$M,(原始订单表!$A:$A=2)*(原始订单表!$B:$B=1)*(原始订单表!$E:$E=S30),0)))} -> 14628 | V30: {=INT(MAX(_xlfn._xlws.FILTER(原始订单表!$M:$M,(原始订单表!$A:$A=2)*(原始订单表!$B:$B=1)*(原始订单表!$E:$E=S30),0)))} -> 15019 | W30: {=INT(MIN(_xlfn._xlws.FILTER(原始订单表!$M:$M,(原始订单表!$A:$A=2)*(原始订单表!$B:$B=2)*(原始订单表!$E:$E=S28),0)))} -> 6818 | X30: {=INT(AVERAGE(_xlfn._xlws.FILTER(原始订单表!$M:$M,(原始订单表!$A:$A=2)*(原始订单表!$B:$B=2)*(原始订单表!$E:$E=S28),0)))} -> 6818 | Y30: {=INT(MAX(_xlfn._xlws.FILTER(原始订单表!$M:$M,(原始订单表!$A:$A=2)*(原始订单表!$B:$B=2)*(原始订单表!$E:$E=S28),0)))} -> 6818 | Z30: 生产总监 | AJ30: 生产总监
B31: 原料成本 | C31: =材料表!D25 -> 0 | D31: =材料表!E25 -> 0 | E31: =材料表!F25 -> 2875000 | F31: =材料表!G25 -> 0 | G31: =H58 -> 0 | H31: {=INT(MIN(_xlfn._xlws.FILTER(原始订单表!$M:$M,(原始订单表!$A:$A=1)*(原始订单表!$B:$B=2)*(原始订单表!$E:$E=G31),0)))} -> 4608 | I31: {=INT(AVERAGE(_xlfn._xlws.FILTER(原始订单表!$M:$M,(原始订单表!$A:$A=1)*(原始订单表!$B:$B=2)*(原始订单表!$E:$E=G31),0)))} -> 4608 | J31: {=INT(MAX(_xlfn._xlws.FILTER(原始订单表!$M:$M,(原始订单表!$A:$A=1)*(原始订单表!$B:$B=2)*(原始订单表!$E:$E=G31),0)))} -> 4608 | K31: {=INT(MIN(_xlfn._xlws.FILTER(原始订单表!$M:$M,(原始订单表!$A:$A=1)*(原始订单表!$B:$B=3)*(原始订单表!$E:$E=G31),0)))} -> 0 | L31: {=INT(AVERAGE(_xlfn._xlws.FILTER(原始订单表!$M:$M,(原始订单表!$A:$A=1)*(原始订单表!$B:$B=3)*(原始订单表!$E:$E=G31),0)))} -> 0 | M31: {=INT(MAX(_xlfn._xlws.FILTER(原始订单表!$M:$M,(原始订单表!$A:$A=1)*(原始订单表!$B:$B=3)*(原始订单表!$E:$E=G31),0)))} -> 0 | N31: 原料成本 | O31: =材料表!H25 -> 2875000 | P31: =材料表!I25 -> 0 | Q31: =材料表!J25 -> 2875000 | R31: =材料表!K25 -> 0 | S31: =G31 -> 0 | T31: {=INT(MIN(_xlfn._xlws.FILTER(原始订单表!$M:$M,(原始订单表!$A:$A=2)*(原始订单表!$B:$B=1)*(原始订单表!$E:$E=S31),0)))} -> 0 | U31: {=INT(AVERAGE(_xlfn._xlws.FILTER(原始订单表!$M:$M,(原始订单表!$A:$A=2)*(原始订单表!$B:$B=1)*(原始订单表!$E:$E=S31),0)))} -> 0 | V31: {=INT(MAX(_xlfn._xlws.FILTER(原始订单表!$M:$M,(原始订单表!$A:$A=2)*(原始订单表!$B:$B=1)*(原始订单表!$E:$E=S31),0)))} -> 0 | W31: {=INT(MIN(_xlfn._xlws.FILTER(原始订单表!$M:$M,(原始订单表!$A:$A=2)*(原始订单表!$B:$B=2)*(原始订单表!$E:$E=S29),0)))} -> 9257 | X31: {=INT(AVERAGE(_xlfn._xlws.FILTER(原始订单表!$M:$M,(原始订单表!$A:$A=2)*(原始订单表!$B:$B=2)*(原始订单表!$E:$E=S29),0)))} -> 9450 | Y31: {=INT(MAX(_xlfn._xlws.FILTER(原始订单表!$M:$M,(原始订单表!$A:$A=2)*(原始订单表!$B:$B=2)*(原始订单表!$E:$E=S29),0)))} -> 9644 | Z31: 原料成本 | AA31: =材料表!L25 -> 0 | AB31: =材料表!M25 -> 0 | AC31: =材料表!N25 -> 0 | AD31: =材料表!O25 -> 0 | AJ31: 原料成本 | AK31: =材料表!P25 -> 0 | AL31: =材料表!Q25 -> 0 | AM31: =材料表!R25 -> 0 | AN31: =材料表!S25 -> 0
B32: 机器设备 | C32: =生产建设!I51 -> 1000000 | D32: =生产建设!J51 -> 0 | E32: =生产建设!K51 -> 0 | F32: =生产建设!L51 -> 0 | N32: 机器设备 | O32: =生产建设!M51 -> 0 | P32: =生产建设!N51 -> 0 | Q32: =生产建设!O51 -> 0 | R32: =生产建设!P51 -> 0 | W32: {=INT(MIN(_xlfn._xlws.FILTER(原始订单表!$M:$M,(原始订单表!$A:$A=2)*(原始订单表!$B:$B=2)*(原始订单表!$E:$E=S30),0)))} -> 12740 | X32: {=INT(AVERAGE(_xlfn._xlws.FILTER(原始订单表!$M:$M,(原始订单表!$A:$A=2)*(原始订单表!$B:$B=2)*(原始订单表!$E:$E=S30),0)))} -> 12901 | Y32: {=INT(MAX(_xlfn._xlws.FILTER(原始订单表!$M:$M,(原始订单表!$A:$A=2)*(原始订单表!$B:$B=2)*(原始订单表!$E:$E=S30),0)))} -> 13063 | Z32: 机器设备 | AA32: =生产建设!Q51 -> 0 | AB32: =生产建设!R51 -> 0 | AC32: =生产建设!S51 -> 0 | AD32: =生产建设!T51 -> 0 | AJ32: 机器设备 | AK32: =生产建设!U52 -> 0 | AL32: =生产建设!V52 -> 0 | AM32: =生产建设!W52 -> 0 | AN32: =生产建设!X52 -> 0
B33: 产品设计 | N33: 产品设计 | W33: {=INT(MIN(_xlfn._xlws.FILTER(原始订单表!$M:$M,(原始订单表!$A:$A=2)*(原始订单表!$B:$B=2)*(原始订单表!$E:$E=S31),0)))} -> 0 | X33: {=INT(AVERAGE(_xlfn._xlws.FILTER(原始订单表!$M:$M,(原始订单表!$A:$A=2)*(原始订单表!$B:$B=2)*(原始订单表!$E:$E=S31),0)))} -> 0 | Y33: {=INT(MAX(_xlfn._xlws.FILTER(原始订单表!$M:$M,(原始订单表!$A:$A=2)*(原始订单表!$B:$B=2)*(原始订单表!$E:$E=S31),0)))} -> 0 | Z33: 产品设计 | AJ33: 产品设计
B34: 特性研发 | N34: 特性研发 | Z34: 特性研发 | AJ34: 特性研发
B35: 转产 | C35: =生产建设!I56 -> 0 | D35: =生产建设!J56 -> 0 | E35: =生产建设!K56 -> 0 | F35: =生产建设!L56 -> 0 | H35: （计算的是成本） | I35: =规则表!B35 -> 传统线 | J35: =规则表!C35 -> 自动线 | K35: =规则表!D35 -> 智能线 | N35: 转产 | O35: =生产建设!M56 -> 0 | P35: =生产建设!N56 -> 0 | Q35: =生产建设!O56 -> 0 | R35: =生产建设!P56 -> 0 | Z35: 转产 | AA35: =生产建设!Q56 -> 0 | AB35: =生产建设!R56 -> 0 | AC35: =生产建设!S56 -> 0 | AD35: =生产建设!T56 -> 0 | AJ35: 转产 | AK35: =生产建设!U56 -> 0 | AL35: =生产建设!V56 -> 0 | AM35: =生产建设!W56 -> 0 | AN35: =生产建设!X56 -> 0
B36: 生产费用 | D36: =材料表!E26 -> 0 | E36: =材料表!F26 -> 125000 | F36: =材料表!G26 -> 0 | H36: =规则表!A36 -> P1 | I36: =规则表!B36 -> 748.8 | J36: =规则表!C36 -> 676.28205 | K36: =规则表!D36 -> 770.36082 | N36: 生产费用 | O36: =材料表!H26 -> 125000 | P36: =材料表!I26 -> 0 | Q36: =材料表!J26 -> 125000 | R36: =材料表!K26 -> 0 | Z36: 生产费用 | AA36: =材料表!L26 -> 0 | AB36: =材料表!M26 -> 0 | AC36: =材料表!N26 -> 0 | AD36: =材料表!O26 -> 0 | AJ36: 生产费用 | AK36: =材料表!P26 -> 0 | AL36: =材料表!Q26 -> 0 | AM36: =材料表!R26 -> 0 | AN36: =材料表!S26 -> 0
B37: 维护费 | H37: =规则表!A37 -> P2 | I37: =规则表!B37 -> 1148.8 | J37: =规则表!C37 -> 1076.2821 | K37: =规则表!D37 -> 1170.3608 | N37: 维护费 | O37: =生产建设!M52 -> 0 | P37: =生产建设!N52 -> 0 | Q37: =生产建设!O52 -> 0 | R37: =生产建设!P52 -> 0 | T37: （计算的是成本） | U37: =U17 -> 利润留存 | V37: =U18 -> 年度净利 | W37: =U19 -> 权益合计 | Z37: 维护费 | AJ37: 维护费
B38: 预算 | C38: =SUM(C31:C36) -> 1000000 | D38: =SUM(D31:D36) -> 0 | E38: =SUM(E31:E36) -> 3000000 | F38: =SUM(F31:F36) -> 0 | H38: =规则表!A38 -> P3 | I38: =规则表!B38 -> 1748.8 | J38: =规则表!C38 -> 1676.2821 | K38: =规则表!D38 -> 1770.3608 | N38: 预算 | O38: =SUM(O31:O36) -> 3000000 | P38: =SUM(P31:P36) -> 0 | Q38: =SUM(Q31:Q36) -> 3000000 | R38: =SUM(R31:R36) -> 0 | T38: =H36 -> P1 | U38: =I36 -> 748.8 | V38: =J36 -> 676.28205 | W38: =K36 -> 770.36082 | Z38: 预算 | AA38: =SUM(AA31:AA36) -> 0 | AB38: =SUM(AB31:AB36) -> 0 | AC38: =SUM(AC31:AC36) -> 0 | AD38: =SUM(AD31:AD36) -> 0 | AJ38: 预算 | AK38: =SUM(AK31:AK36) -> 0 | AL38: =SUM(AL31:AL36) -> 0 | AM38: =SUM(AM31:AM36) -> 0 | AN38: =SUM(AN31:AN36) -> 0
B39: 营销总监 | H39: =规则表!A39 -> P4 | I39: =规则表!B39 -> 2548.8 | J39: =规则表!C39 -> 2476.2821 | K39: =规则表!D39 -> 2570.3608 | N39: 营销总监 | T39: =H37 -> P2 | U39: =I37 -> 1148.8 | V39: =J37 -> 1076.2821 | W39: =K37 -> 1170.3608 | Z39: 营销总监 | AJ39: 营销总监
B40: 产品资质 | C40: {=SUM(IF($K$54:$K$58<=1,$I$54:$I$58,0))} -> 210000 | D40: {=SUM(IF($K$54:$K$58=2,$I$54:$I$58,0))} -> 0 | E40: {=SUM(IF($K$54:$K$58=3,$I$54:$I$58,0))} -> 0 | F40: {=SUM(IF($K$54:$K$58=4,$I$54:$I$58,0))} -> 0 | H40: =规则表!A40 -> 0 | I40: =规则表!B40 -> 248.8 | J40: =规则表!C40 -> 176.28205 | K40: =规则表!D40 -> 270.36082 | N40: 产品资质 | O40: {=SUM(IF($K$54:$K$58=5,$I$54:$I$58,0))} -> 0 | P40: {=SUM(IF($K$54:$K$58=6,$I$54:$I$58,0))} -> 0 | Q40: {=SUM(IF($K$54:$K$58=7,$I$54:$I$58,0))} -> 0 | R40: {=SUM(IF($K$54:$K$58=8,$I$54:$I$58,0))} -> 0 | T40: =H38 -> P3 | U40: =I38 -> 1748.8 | V40: =J38 -> 1676.2821 | W40: =K38 -> 1770.3608 | Z40: 产品资质 | AA40: {=SUM(IF($K$54:$K$58=9,$I$54:$I$58,0))} -> 0 | AB40: {=SUM(IF($K$54:$K$58=10,$I$54:$I$58,0))} -> 0 | AC40: {=SUM(IF($K$54:$K$58=11,$I$54:$I$58,0))} -> 0 | AD40: {=SUM(IF($K$54:$K$58=12,$I$54:$I$58,0))} -> 0 | AJ40: 产品资质 | AK40: {=SUM(IF($K$54:$K$58=13,$I$54:$I$58,0))} -> 0 | AL40: {=SUM(IF($K$54:$K$58=14,$I$54:$I$58,0))} -> 0 | AM40: {=SUM(IF($K$54:$K$58=15,$I$54:$I$58,0))} -> 0 | AN40: {=SUM(IF($K$54:$K$58=16,$I$54:$I$58,0))} -> 0
...

Sheet 生产建设
A1: 涨薪 | B1: 激励 | I1: 第一年 | M1: 第二年 | Q1: 第三年 | U1: 第四年
I2: 1 | J2: 2 | K2: 3 | L2: 4 | M2: 1 | N2: 2 | O2: 3 | P2: 4 | Q2: 1 | R2: 2 | S2: 3 | T2: 4 | U2: 1 | V2: 2 | W2: 3 | X2: 4
A3: 涨薪方案选择 | I3: 激励 | J3: 激励 | K3: 激励 | L3: 激励 | M3: 激励 | N3: 激励 | O3: 激励 | P3: 激励 | Q3: 激励 | R3: 激励 | S3: 激励 | T3: 激励 | U3: 激励 | V3: 激励 | W3: 激励 | X3: 激励
A4: 建设计划 | B4: 传统线 | C4: P1
C5: P2
C6: P3
C7: P4 | I7: 10
C8: P5
B9: 自动线 | C9: P1
C10: P2
C11: P3
C12: P4
C13: P5
B14: 智能线 | C14: P1
C15: P2
C16: P3
C17: P4
C18: P5
A20: 拆线计划 | B20: 传统线 | C20: P1
C21: P2
C22: P3
C23: P4
C24: P5
B25: 自动线 | C25: P1
C26: P2
C27: P3
C28: P4
C29: P5
B30: 智能线 | C30: P1
C31: P2
C32: P3
C33: P4
C34: P5
A36: 转产计划 | B36: 传统线 | C36: P1
C37: P2
C38: P3
C39: P4
C40: P5
B41: 自动线 | C41: P1
C42: P2
...

Sheet 材料表
A1: 8小时 | B1: 12小时 | D1: 第一年 | H1: 第二年 | L1: 第三年 | P1: 第四年
D2: 1 | E2: 2 | F2: 3 | G2: 4 | H2: 1 | I2: 2 | J2: 3 | K2: 4 | L2: 1 | M2: 2 | N2: 3 | O2: 4 | P2: 1 | Q2: 2 | R2: 3 | S2: 4
A3: 班次选择 | D3: 8小时 | E3: 8小时 | F3: 8小时 | G3: 8小时 | H3: 8小时 | I3: 8小时 | J3: 8小时 | K3: 8小时 | L3: 8小时 | M3: 8小时 | N3: 8小时 | O3: 8小时 | P3: 8小时 | Q3: 8小时 | R3: 8小时 | S3: 8小时
A4: 生产计划（当季度开产产品数量） | B4: 传统线 | C4: P1 | D4: =生产建设!I94*规则表!$P$17*(D$3="8小时")+生产建设!I94*规则表!$Q$17*(D$3="12小时") -> 0 | E4: =生产建设!J94*规则表!$P$17*(E$3="8小时")+生产建设!J94*规则表!$Q$17*(E$3="12小时") -> 0 | F4: =生产建设!K94*规则表!$P$17*(F$3="8小时")+生产建设!K94*规则表!$Q$17*(F$3="12小时") -> 0 | G4: =生产建设!L94*规则表!$P$17*(G$3="8小时")+生产建设!L94*规则表!$Q$17*(G$3="12小时") -> 0 | H4: =生产建设!M94*规则表!$P$17*(H$3="8小时")+生产建设!M94*规则表!$Q$17*(H$3="12小时") -> 0 | I4: =生产建设!N94*规则表!$P$17*(I$3="8小时")+生产建设!N94*规则表!$Q$17*(I$3="12小时") -> 0 | J4: =生产建设!O94*规则表!$P$17*(J$3="8小时")+生产建设!O94*规则表!$Q$17*(J$3="12小时") -> 0 | K4: =生产建设!P94*规则表!$P$17*(K$3="8小时")+生产建设!P94*规则表!$Q$17*(K$3="12小时") -> 0 | ... S4: =生产建设!X94*规则表!$P$17*(S$3="8小时")+生产建设!X94*规则表!$Q$17*(S$3="12小时") -> 0
C5: P2 | D5: =生产建设!I95*规则表!$P$17*(D$3="8小时")+生产建设!I95*规则表!$Q$17*(D$3="12小时") -> 0 | E5: =生产建设!J95*规则表!$P$17*(E$3="8小时")+生产建设!J95*规则表!$Q$17*(E$3="12小时") -> 0 | F5: =生产建设!K95*规则表!$P$17*(F$3="8小时")+生产建设!K95*规则表!$Q$17*(F$3="12小时") -> 0 | G5: =生产建设!L95*规则表!$P$17*(G$3="8小时")+生产建设!L95*规则表!$Q$17*(G$3="12小时") -> 0 | H5: =生产建设!M95*规则表!$P$17*(H$3="8小时")+生产建设!M95*规则表!$Q$17*(H$3="12小时") -> 0 | I5: =生产建设!N95*规则表!$P$17*(I$3="8小时")+生产建设!N95*规则表!$Q$17*(I$3="12小时") -> 0 | J5: =生产建设!O95*规则表!$P$17*(J$3="8小时")+生产建设!O95*规则表!$Q$17*(J$3="12小时") -> 0 | K5: =生产建设!P95*规则表!$P$17*(K$3="8小时")+生产建设!P95*规则表!$Q$17*(K$3="12小时") -> 0 | ... S5: =生产建设!X95*规则表!$P$17*(S$3="8小时")+生产建设!X95*规则表!$Q$17*(S$3="12小时") -> 0
C6: P3 | D6: =生产建设!I96*规则表!$P$17*(D$3="8小时")+生产建设!I96*规则表!$Q$17*(D$3="12小时") -> 0 | E6: =生产建设!J96*规则表!$P$17*(E$3="8小时")+生产建设!J96*规则表!$Q$17*(E$3="12小时") -> 0 | F6: =生产建设!K96*规则表!$P$17*(F$3="8小时")+生产建设!K96*规则表!$Q$17*(F$3="12小时") -> 0 | G6: =生产建设!L96*规则表!$P$17*(G$3="8小时")+生产建设!L96*规则表!$Q$17*(G$3="12小时") -> 0 | H6: =生产建设!M96*规则表!$P$17*(H$3="8小时")+生产建设!M96*规则表!$Q$17*(H$3="12小时") -> 0 | I6: =生产建设!N96*规则表!$P$17*(I$3="8小时")+生产建设!N96*规则表!$Q$17*(I$3="12小时") -> 0 | J6: =生产建设!O96*规则表!$P$17*(J$3="8小时")+生产建设!O96*规则表!$Q$17*(J$3="12小时") -> 0 | K6: =生产建设!P96*规则表!$P$17*(K$3="8小时")+生产建设!P96*规则表!$Q$17*(K$3="12小时") -> 0 | ... S6: =生产建设!X96*规则表!$P$17*(S$3="8小时")+生产建设!X96*规则表!$Q$17*(S$3="12小时") -> 0
C7: P4 | D7: =生产建设!I97*规则表!$P$17*(D$3="8小时")+生产建设!I97*规则表!$Q$17*(D$3="12小时") -> 1250 | E7: =生产建设!J97*规则表!$P$17*(E$3="8小时")+生产建设!J97*规则表!$Q$17*(E$3="12小时") -> 0 | F7: =生产建设!K97*规则表!$P$17*(F$3="8小时")+生产建设!K97*规则表!$Q$17*(F$3="12小时") -> 1250 | G7: =生产建设!L97*规则表!$P$17*(G$3="8小时")+生产建设!L97*规则表!$Q$17*(G$3="12小时") -> 0 | H7: =生产建设!M97*规则表!$P$17*(H$3="8小时")+生产建设!M97*规则表!$Q$17*(H$3="12小时") -> 1250 | I7: =生产建设!N97*规则表!$P$17*(I$3="8小时")+生产建设!N97*规则表!$Q$17*(I$3="12小时") -> 0 | J7: =生产建设!O97*规则表!$P$17*(J$3="8小时")+生产建设!O97*规则表!$Q$17*(J$3="12小时") -> 1250 | K7: =生产建设!P97*规则表!$P$17*(K$3="8小时")+生产建设!P97*规则表!$Q$17*(K$3="12小时") -> 0 | ... S7: =生产建设!X97*规则表!$P$17*(S$3="8小时")+生产建设!X97*规则表!$Q$17*(S$3="12小时") -> 0
C8: P5 | D8: =生产建设!I98*规则表!$P$17*(D$3="8小时")+生产建设!I98*规则表!$Q$17*(D$3="12小时") -> 0 | E8: =生产建设!J98*规则表!$P$17*(E$3="8小时")+生产建设!J98*规则表!$Q$17*(E$3="12小时") -> 0 | F8: =生产建设!K98*规则表!$P$17*(F$3="8小时")+生产建设!K98*规则表!$Q$17*(F$3="12小时") -> 0 | G8: =生产建设!L98*规则表!$P$17*(G$3="8小时")+生产建设!L98*规则表!$Q$17*(G$3="12小时") -> 0 | H8: =生产建设!M98*规则表!$P$17*(H$3="8小时")+生产建设!M98*规则表!$Q$17*(H$3="12小时") -> 0 | I8: =生产建设!N98*规则表!$P$17*(I$3="8小时")+生产建设!N98*规则表!$Q$17*(I$3="12小时") -> 0 | J8: =生产建设!O98*规则表!$P$17*(J$3="8小时")+生产建设!O98*规则表!$Q$17*(J$3="12小时") -> 0 | K8: =生产建设!P98*规则表!$P$17*(K$3="8小时")+生产建设!P98*规则表!$Q$17*(K$3="12小时") -> 0 | ... S8: =生产建设!X98*规则表!$P$17*(S$3="8小时")+生产建设!X98*规则表!$Q$17*(S$3="12小时") -> 0
B9: 自动线 | C9: P1 | D9: =生产建设!I99*规则表!$P$18*(D$3="8小时")+生产建设!I99*规则表!$Q$18*(D$3="12小时") -> 0 | E9: =生产建设!J99*规则表!$P$18*(E$3="8小时")+生产建设!J99*规则表!$Q$18*(E$3="12小时") -> 0 | F9: =生产建设!K99*规则表!$P$18*(F$3="8小时")+生产建设!K99*规则表!$Q$18*(F$3="12小时") -> 0 | G9: =生产建设!L99*规则表!$P$18*(G$3="8小时")+生产建设!L99*规则表!$Q$18*(G$3="12小时") -> 0 | H9: =生产建设!M99*规则表!$P$18*(H$3="8小时")+生产建设!M99*规则表!$Q$18*(H$3="12小时") -> 0 | I9: =生产建设!N99*规则表!$P$18*(I$3="8小时")+生产建设!N99*规则表!$Q$18*(I$3="12小时") -> 0 | J9: =生产建设!O99*规则表!$P$18*(J$3="8小时")+生产建设!O99*规则表!$Q$18*(J$3="12小时") -> 0 | K9: =生产建设!P99*规则表!$P$18*(K$3="8小时")+生产建设!P99*规则表!$Q$18*(K$3="12小时") -> 0 | ... S9: =生产建设!X99*规则表!$P$18*(S$3="8小时")+生产建设!X99*规则表!$Q$18*(S$3="12小时") -> 0
C10: P2 | D10: =生产建设!I100*规则表!$P$18*(D$3="8小时")+生产建设!I100*规则表!$Q$18*(D$3="12小时") -> 0 | E10: =生产建设!J100*规则表!$P$18*(E$3="8小时")+生产建设!J100*规则表!$Q$18*(E$3="12小时") -> 0 | F10: =生产建设!K100*规则表!$P$18*(F$3="8小时")+生产建设!K100*规则表!$Q$18*(F$3="12小时") -> 0 | G10: =生产建设!L100*规则表!$P$18*(G$3="8小时")+生产建设!L100*规则表!$Q$18*(G$3="12小时") -> 0 | H10: =生产建设!M100*规则表!$P$18*(H$3="8小时")+生产建设!M100*规则表!$Q$18*(H$3="12小时") -> 0 | I10: =生产建设!N100*规则表!$P$18*(I$3="8小时")+生产建设!N100*规则表!$Q$18*(I$3="12小时") -> 0 | J10: =生产建设!O100*规则表!$P$18*(J$3="8小时")+生产建设!O100*规则表!$Q$18*(J$3="12小时") -> 0 | K10: =生产建设!P100*规则表!$P$18*(K$3="8小时")+生产建设!P100*规则表!$Q$18*(K$3="12小时") -> 0 | ... S10: =生产建设!X100*规则表!$P$18*(S$3="8小时")+生产建设!X100*规则表!$Q$18*(S$3="12小时") -> 0
C11: P3 | D11: =生产建设!I101*规则表!$P$18*(D$3="8小时")+生产建设!I101*规则表!$Q$18*(D$3="12小时") -> 0 | E11: =生产建设!J101*规则表!$P$18*(E$3="8小时")+生产建设!J101*规则表!$Q$18*(E$3="12小时") -> 0 | F11: =生产建设!K101*规则表!$P$18*(F$3="8小时")+生产建设!K101*规则表!$Q$18*(F$3="12小时") -> 0 | G11: =生产建设!L101*规则表!$P$18*(G$3="8小时")+生产建设!L101*规则表!$Q$18*(G$3="12小时") -> 0 | H11: =生产建设!M101*规则表!$P$18*(H$3="8小时")+生产建设!M101*规则表!$Q$18*(H$3="12小时") -> 0 | I11: =生产建设!N101*规则表!$P$18*(I$3="8小时")+生产建设!N101*规则表!$Q$18*(I$3="12小时") -> 0 | J11: =生产建设!O101*规则表!$P$18*(J$3="8小时")+生产建设!O101*规则表!$Q$18*(J$3="12小时") -> 0 | K11: =生产建设!P101*规则表!$P$18*(K$3="8小时")+生产建设!P101*规则表!$Q$18*(K$3="12小时") -> 0 | ... S11: =生产建设!X101*规则表!$P$18*(S$3="8小时")+生产建设!X101*规则表!$Q$18*(S$3="12小时") -> 0
C12: P4 | D12: =生产建设!I102*规则表!$P$18*(D$3="8小时")+生产建设!I102*规则表!$Q$18*(D$3="12小时") -> 0 | E12: =生产建设!J102*规则表!$P$18*(E$3="8小时")+生产建设!J102*规则表!$Q$18*(E$3="12小时") -> 0 | F12: =生产建设!K102*规则表!$P$18*(F$3="8小时")+生产建设!K102*规则表!$Q$18*(F$3="12小时") -> 0 | G12: =生产建设!L102*规则表!$P$18*(G$3="8小时")+生产建设!L102*规则表!$Q$18*(G$3="12小时") -> 0 | H12: =生产建设!M102*规则表!$P$18*(H$3="8小时")+生产建设!M102*规则表!$Q$18*(H$3="12小时") -> 0 | I12: =生产建设!N102*规则表!$P$18*(I$3="8小时")+生产建设!N102*规则表!$Q$18*(I$3="12小时") -> 0 | J12: =生产建设!O102*规则表!$P$18*(J$3="8小时")+生产建设!O102*规则表!$Q$18*(J$3="12小时") -> 0 | K12: =生产建设!P102*规则表!$P$18*(K$3="8小时")+生产建设!P102*规则表!$Q$18*(K$3="12小时") -> 0 | ... S12: =生产建设!X102*规则表!$P$18*(S$3="8小时")+生产建设!X102*规则表!$Q$18*(S$3="12小时") -> 0
C13: P5 | D13: =生产建设!I103*规则表!$P$18*(D$3="8小时")+生产建设!I103*规则表!$Q$18*(D$3="12小时") -> 0 | E13: =生产建设!J103*规则表!$P$18*(E$3="8小时")+生产建设!J103*规则表!$Q$18*(E$3="12小时") -> 0 | F13: =生产建设!K103*规则表!$P$18*(F$3="8小时")+生产建设!K103*规则表!$Q$18*(F$3="12小时") -> 0 | G13: =生产建设!L103*规则表!$P$18*(G$3="8小时")+生产建设!L103*规则表!$Q$18*(G$3="12小时") -> 0 | H13: =生产建设!M103*规则表!$P$18*(H$3="8小时")+生产建设!M103*规则表!$Q$18*(H$3="12小时") -> 0 | I13: =生产建设!N103*规则表!$P$18*(I$3="8小时")+生产建设!N103*规则表!$Q$18*(I$3="12小时") -> 0 | J13: =生产建设!O103*规则表!$P$18*(J$3="8小时")+生产建设!O103*规则表!$Q$18*(J$3="12小时") -> 0 | K13: =生产建设!P103*规则表!$P$18*(K$3="8小时")+生产建设!P103*规则表!$Q$18*(K$3="12小时") -> 0 | ... S13: =生产建设!X103*规则表!$P$18*(S$3="8小时")+生产建设!X103*规则表!$Q$18*(S$3="12小时") -> 0
B14: 智能线 | C14: P1 | D14: =生产建设!I104*规则表!$P$19*(D$3="8小时")+生产建设!I104*规则表!$P$19*(D$3="12小时") -> 0 | E14: =生产建设!J104*规则表!$P$19*(E$3="8小时")+生产建设!J104*规则表!$P$19*(E$3="12小时") -> 0 | F14: =生产建设!K104*规则表!$P$19*(F$3="8小时")+生产建设!K104*规则表!$P$19*(F$3="12小时") -> 0 | G14: =生产建设!L104*规则表!$P$19*(G$3="8小时")+生产建设!L104*规则表!$P$19*(G$3="12小时") -> 0 | H14: =生产建设!M104*规则表!$P$19*(H$3="8小时")+生产建设!M104*规则表!$P$19*(H$3="12小时") -> 0 | I14: =生产建设!N104*规则表!$P$19*(I$3="8小时")+生产建设!N104*规则表!$P$19*(I$3="12小时") -> 0 | J14: =生产建设!O104*规则表!$P$19*(J$3="8小时")+生产建设!O104*规则表!$P$19*(J$3="12小时") -> 0 | K14: =生产建设!P104*规则表!$P$19*(K$3="8小时")+生产建设!P104*规则表!$P$19*(K$3="12小时") -> 0 | ... S14: =生产建设!X104*规则表!$P$19*(S$3="8小时")+生产建设!X104*规则表!$P$19*(S$3="12小时") -> 0
C15: P2 | D15: =生产建设!I105*规则表!$P$19*(D$3="8小时")+生产建设!I105*规则表!$P$19*(D$3="12小时") -> 0 | E15: =生产建设!J105*规则表!$P$19*(E$3="8小时")+生产建设!J105*规则表!$P$19*(E$3="12小时") -> 0 | F15: =生产建设!K105*规则表!$P$19*(F$3="8小时")+生产建设!K105*规则表!$P$19*(F$3="12小时") -> 0 | G15: =生产建设!L105*规则表!$P$19*(G$3="8小时")+生产建设!L105*规则表!$P$19*(G$3="12小时") -> 0 | H15: =生产建设!M105*规则表!$P$19*(H$3="8小时")+生产建设!M105*规则表!$P$19*(H$3="12小时") -> 0 | I15: =生产建设!N105*规则表!$P$19*(I$3="8小时")+生产建设!N105*规则表!$P$19*(I$3="12小时") -> 0 | J15: =生产建设!O105*规则表!$P$19*(J$3="8小时")+生产建设!O105*规则表!$P$19*(J$3="12小时") -> 0 | K15: =生产建设!P105*规则表!$P$19*(K$3="8小时")+生产建设!P105*规则表!$P$19*(K$3="12小时") -> 0 | ... S15: =生产建设!X105*规则表!$P$19*(S$3="8小时")+生产建设!X105*规则表!$P$19*(S$3="12小时") -> 0
C16: P3 | D16: =生产建设!I106*规则表!$P$19*(D$3="8小时")+生产建设!I106*规则表!$P$19*(D$3="12小时") -> 0 | E16: =生产建设!J106*规则表!$P$19*(E$3="8小时")+生产建设!J106*规则表!$P$19*(E$3="12小时") -> 0 | F16: =生产建设!K106*规则表!$P$19*(F$3="8小时")+生产建设!K106*规则表!$P$19*(F$3="12小时") -> 0 | G16: =生产建设!L106*规则表!$P$19*(G$3="8小时")+生产建设!L106*规则表!$P$19*(G$3="12小时") -> 0 | H16: =生产建设!M106*规则表!$P$19*(H$3="8小时")+生产建设!M106*规则表!$P$19*(H$3="12小时") -> 0 | I16: =生产建设!N106*规则表!$P$19*(I$3="8小时")+生产建设!N106*规则表!$P$19*(I$3="12小时") -> 0 | J16: =生产建设!O106*规则表!$P$19*(J$3="8小时")+生产建设!O106*规则表!$P$19*(J$3="12小时") -> 0 | K16: =生产建设!P106*规则表!$P$19*(K$3="8小时")+生产建设!P106*规则表!$P$19*(K$3="12小时") -> 0 | ... S16: =生产建设!X106*规则表!$P$19*(S$3="8小时")+生产建设!X106*规则表!$P$19*(S$3="12小时") -> 0
C17: P4 | D17: =生产建设!I107*规则表!$P$19*(D$3="8小时")+生产建设!I107*规则表!$P$19*(D$3="12小时") -> 0 | E17: =生产建设!J107*规则表!$P$19*(E$3="8小时")+生产建设!J107*规则表!$P$19*(E$3="12小时") -> 0 | F17: =生产建设!K107*规则表!$P$19*(F$3="8小时")+生产建设!K107*规则表!$P$19*(F$3="12小时") -> 0 | G17: =生产建设!L107*规则表!$P$19*(G$3="8小时")+生产建设!L107*规则表!$P$19*(G$3="12小时") -> 0 | H17: =生产建设!M107*规则表!$P$19*(H$3="8小时")+生产建设!M107*规则表!$P$19*(H$3="12小时") -> 0 | I17: =生产建设!N107*规则表!$P$19*(I$3="8小时")+生产建设!N107*规则表!$P$19*(I$3="12小时") -> 0 | J17: =生产建设!O107*规则表!$P$19*(J$3="8小时")+生产建设!O107*规则表!$P$19*(J$3="12小时") -> 0 | K17: =生产建设!P107*规则表!$P$19*(K$3="8小时")+生产建设!P107*规则表!$P$19*(K$3="12小时") -> 0 | ... S17: =生产建设!X107*规则表!$P$19*(S$3="8小时")+生产建设!X107*规则表!$P$19*(S$3="12小时") -> 0
C18: P5 | D18: =生产建设!I108*规则表!$P$19*(D$3="8小时")+生产建设!I108*规则表!$P$19*(D$3="12小时") -> 0 | E18: =生产建设!J108*规则表!$P$19*(E$3="8小时")+生产建设!J108*规则表!$P$19*(E$3="12小时") -> 0 | F18: =生产建设!K108*规则表!$P$19*(F$3="8小时")+生产建设!K108*规则表!$P$19*(F$3="12小时") -> 0 | G18: =生产建设!L108*规则表!$P$19*(G$3="8小时")+生产建设!L108*规则表!$P$19*(G$3="12小时") -> 0 | H18: =生产建设!M108*规则表!$P$19*(H$3="8小时")+生产建设!M108*规则表!$P$19*(H$3="12小时") -> 0 | I18: =生产建设!N108*规则表!$P$19*(I$3="8小时")+生产建设!N108*规则表!$P$19*(I$3="12小时") -> 0 | J18: =生产建设!O108*规则表!$P$19*(J$3="8小时")+生产建设!O108*规则表!$P$19*(J$3="12小时") -> 0 | K18: =生产建设!P108*规则表!$P$19*(K$3="8小时")+生产建设!P108*规则表!$P$19*(K$3="12小时") -> 0 | ... S18: =生产建设!X108*规则表!$P$19*(S$3="8小时")+生产建设!X108*规则表!$P$19*(S$3="12小时") -> 0
B20: 采购计划 | C20: R1 | D20: {=SUMPRODUCT(INDEX($C$4:$S$8,,COLUMN()+$C$52-2),$C$47:$C$51)+SUMPRODUCT(INDEX($C$9:$S$13,,COLUMN()+$C$52-2),$C$47:$C$51)+SUMPRODUCT(INDEX($C$14:$S$18,,COLUMN()+$C$52-2),$C$47:$C$51)} -> 0 | E20: {=SUMPRODUCT(INDEX($C$4:$S$8,,COLUMN()+$C$52-2),$C$47:$C$51)+SUMPRODUCT(INDEX($C$9:$S$13,,COLUMN()+$C$52-2),$C$47:$C$51)+SUMPRODUCT(INDEX($C$14:$S$18,,COLUMN()+$C$52-2),$C$47:$C$51)} -> 7500 | F20: {=SUMPRODUCT(INDEX($C$4:$S$8,,COLUMN()+$C$52-2),$C$47:$C$51)+SUMPRODUCT(INDEX($C$9:$S$13,,COLUMN()+$C$52-2),$C$47:$C$51)+SUMPRODUCT(INDEX($C$14:$S$18,,COLUMN()+$C$52-2),$C$47:$C$51)} -> 0 | G20: {=SUMPRODUCT(INDEX($C$4:$S$8,,COLUMN()+$C$52-2),$C$47:$C$51)+SUMPRODUCT(INDEX($C$9:$S$13,,COLUMN()+$C$52-2),$C$47:$C$51)+SUMPRODUCT(INDEX($C$14:$S$18,,COLUMN()+$C$52-2),$C$47:$C$51)} -> 7500 | H20: {=SUMPRODUCT(INDEX($C$4:$S$8,,COLUMN()+$C$52-2),$C$47:$C$51)+SUMPRODUCT(INDEX($C$9:$S$13,,COLUMN()+$C$52-2),$C$47:$C$51)+SUMPRODUCT(INDEX($C$14:$S$18,,COLUMN()+$C$52-2),$C$47:$C$51)} -> 0 | I20: {=SUMPRODUCT(INDEX($C$4:$S$8,,COLUMN()+$C$52-2),$C$47:$C$51)+SUMPRODUCT(INDEX($C$9:$S$13,,COLUMN()+$C$52-2),$C$47:$C$51)+SUMPRODUCT(INDEX($C$14:$S$18,,COLUMN()+$C$52-2),$C$47:$C$51)} -> 7500 | J20: {=SUMPRODUCT(INDEX($C$4:$S$8,,COLUMN()+$C$52-2),$C$47:$C$51)+SUMPRODUCT(INDEX($C$9:$S$13,,COLUMN()+$C$52-2),$C$47:$C$51)+SUMPRODUCT(INDEX($C$14:$S$18,,COLUMN()+$C$52-2),$C$47:$C$51)} -> 0 | K20: {=SUMPRODUCT(INDEX($C$4:$S$8,,COLUMN()+$C$52-2),$C$47:$C$51)+SUMPRODUCT(INDEX($C$9:$S$13,,COLUMN()+$C$52-2),$C$47:$C$51)+SUMPRODUCT(INDEX($C$14:$S$18,,COLUMN()+$C$52-2),$C$47:$C$51)} -> 0 | ... S20: {=SUMPRODUCT(INDEX($C$4:$S$8,,COLUMN()+$C$52-2),$C$47:$C$51)+SUMPRODUCT(INDEX($C$9:$S$13,,COLUMN()+$C$52-2),$C$47:$C$51)+SUMPRODUCT(INDEX($C$14:$S$18,,COLUMN()+$C$52-2),$C$47:$C$51)} -> #REF!
C21: R2 | D21: {=SUMPRODUCT(INDEX($C$4:$S$8,,COLUMN()+$D$52-2),$D$47:$D$51)+SUMPRODUCT(INDEX($C$9:$S$13,,COLUMN()+$D$52-2),$D$47:$D$51)+SUMPRODUCT(INDEX($C$14:$S$18,,COLUMN()+$D$52-2),$D$47:$D$51)} -> 0 | E21: {=SUMPRODUCT(INDEX($C$4:$S$8,,COLUMN()+$D$52-2),$D$47:$D$51)+SUMPRODUCT(INDEX($C$9:$S$13,,COLUMN()+$D$52-2),$D$47:$D$51)+SUMPRODUCT(INDEX($C$14:$S$18,,COLUMN()+$D$52-2),$D$47:$D$51)} -> 8750 | F21: {=SUMPRODUCT(INDEX($C$4:$S$8,,COLUMN()+$D$52-2),$D$47:$D$51)+SUMPRODUCT(INDEX($C$9:$S$13,,COLUMN()+$D$52-2),$D$47:$D$51)+SUMPRODUCT(INDEX($C$14:$S$18,,COLUMN()+$D$52-2),$D$47:$D$51)} -> 0 | G21: {=SUMPRODUCT(INDEX($C$4:$S$8,,COLUMN()+$D$52-2),$D$47:$D$51)+SUMPRODUCT(INDEX($C$9:$S$13,,COLUMN()+$D$52-2),$D$47:$D$51)+SUMPRODUCT(INDEX($C$14:$S$18,,COLUMN()+$D$52-2),$D$47:$D$51)} -> 8750 | H21: {=SUMPRODUCT(INDEX($C$4:$S$8,,COLUMN()+$D$52-2),$D$47:$D$51)+SUMPRODUCT(INDEX($C$9:$S$13,,COLUMN()+$D$52-2),$D$47:$D$51)+SUMPRODUCT(INDEX($C$14:$S$18,,COLUMN()+$D$52-2),$D$47:$D$51)} -> 0 | I21: {=SUMPRODUCT(INDEX($C$4:$S$8,,COLUMN()+$D$52-2),$D$47:$D$51)+SUMPRODUCT(INDEX($C$9:$S$13,,COLUMN()+$D$52-2),$D$47:$D$51)+SUMPRODUCT(INDEX($C$14:$S$18,,COLUMN()+$D$52-2),$D$47:$D$51)} -> 8750 | J21: {=SUMPRODUCT(INDEX($C$4:$S$8,,COLUMN()+$D$52-2),$D$47:$D$51)+SUMPRODUCT(INDEX($C$9:$S$13,,COLUMN()+$D$52-2),$D$47:$D$51)+SUMPRODUCT(INDEX($C$14:$S$18,,COLUMN()+$D$52-2),$D$47:$D$51)} -> 0 | K21: {=SUMPRODUCT(INDEX($C$4:$S$8,,COLUMN()+$D$52-2),$D$47:$D$51)+SUMPRODUCT(INDEX($C$9:$S$13,,COLUMN()+$D$52-2),$D$47:$D$51)+SUMPRODUCT(INDEX($C$14:$S$18,,COLUMN()+$D$52-2),$D$47:$D$51)} -> 0 | ... S21: {=SUMPRODUCT(INDEX($C$4:$S$8,,COLUMN()+$D$52-2),$D$47:$D$51)+SUMPRODUCT(INDEX($C$9:$S$13,,COLUMN()+$D$52-2),$D$47:$D$51)+SUMPRODUCT(INDEX($C$14:$S$18,,COLUMN()+$D$52-2),$D$47:$D$51)} -> #REF!
C22: R3 | D22: {=SUMPRODUCT(INDEX($C$4:$S$8,,COLUMN()-2+$E$52),$E$47:$E$51)+SUMPRODUCT(INDEX($C$9:$S$13,,COLUMN()-2+$E$52),$E$47:$E$51)+SUMPRODUCT(INDEX($C$14:$S$18,,COLUMN()-2+$E$52),$E$47:$E$51)} -> 0 | E22: {=SUMPRODUCT(INDEX($C$4:$S$8,,COLUMN()-2+$E$52),$E$47:$E$51)+SUMPRODUCT(INDEX($C$9:$S$13,,COLUMN()-2+$E$52),$E$47:$E$51)+SUMPRODUCT(INDEX($C$14:$S$18,,COLUMN()-2+$E$52),$E$47:$E$51)} -> 6250 | F22: {=SUMPRODUCT(INDEX($C$4:$S$8,,COLUMN()-2+$E$52),$E$47:$E$51)+SUMPRODUCT(INDEX($C$9:$S$13,,COLUMN()-2+$E$52),$E$47:$E$51)+SUMPRODUCT(INDEX($C$14:$S$18,,COLUMN()-2+$E$52),$E$47:$E$51)} -> 0 | G22: {=SUMPRODUCT(INDEX($C$4:$S$8,,COLUMN()-2+$E$52),$E$47:$E$51)+SUMPRODUCT(INDEX($C$9:$S$13,,COLUMN()-2+$E$52),$E$47:$E$51)+SUMPRODUCT(INDEX($C$14:$S$18,,COLUMN()-2+$E$52),$E$47:$E$51)} -> 6250 | H22: {=SUMPRODUCT(INDEX($C$4:$S$8,,COLUMN()-2+$E$52),$E$47:$E$51)+SUMPRODUCT(INDEX($C$9:$S$13,,COLUMN()-2+$E$52),$E$47:$E$51)+SUMPRODUCT(INDEX($C$14:$S$18,,COLUMN()-2+$E$52),$E$47:$E$51)} -> 0 | I22: {=SUMPRODUCT(INDEX($C$4:$S$8,,COLUMN()-2+$E$52),$E$47:$E$51)+SUMPRODUCT(INDEX($C$9:$S$13,,COLUMN()-2+$E$52),$E$47:$E$51)+SUMPRODUCT(INDEX($C$14:$S$18,,COLUMN()-2+$E$52),$E$47:$E$51)} -> 6250 | J22: {=SUMPRODUCT(INDEX($C$4:$S$8,,COLUMN()-2+$E$52),$E$47:$E$51)+SUMPRODUCT(INDEX($C$9:$S$13,,COLUMN()-2+$E$52),$E$47:$E$51)+SUMPRODUCT(INDEX($C$14:$S$18,,COLUMN()-2+$E$52),$E$47:$E$51)} -> 0 | K22: {=SUMPRODUCT(INDEX($C$4:$S$8,,COLUMN()-2+$E$52),$E$47:$E$51)+SUMPRODUCT(INDEX($C$9:$S$13,,COLUMN()-2+$E$52),$E$47:$E$51)+SUMPRODUCT(INDEX($C$14:$S$18,,COLUMN()-2+$E$52),$E$47:$E$51)} -> 0 | ... S22: {=SUMPRODUCT(INDEX($C$4:$S$8,,COLUMN()-2+$E$52),$E$47:$E$51)+SUMPRODUCT(INDEX($C$9:$S$13,,COLUMN()-2+$E$52),$E$47:$E$51)+SUMPRODUCT(INDEX($C$14:$S$18,,COLUMN()-2+$E$52),$E$47:$E$51)} -> #REF!
C23: R4 | D23: {=SUMPRODUCT(INDEX($C$4:$S$8,,COLUMN()-2+$F$52),$F$47:$F$51)+SUMPRODUCT(INDEX($C$9:$S$13,,COLUMN()-2+$F$52),$F$47:$F$51)+SUMPRODUCT(INDEX($C$14:$S$18,,COLUMN()-2+$F$52),$F$47:$F$51)} -> 6250 | E23: {=SUMPRODUCT(INDEX($C$4:$S$8,,COLUMN()-2+$F$52),$F$47:$F$51)+SUMPRODUCT(INDEX($C$9:$S$13,,COLUMN()-2+$F$52),$F$47:$F$51)+SUMPRODUCT(INDEX($C$14:$S$18,,COLUMN()-2+$F$52),$F$47:$F$51)} -> 0 | F23: {=SUMPRODUCT(INDEX($C$4:$S$8,,COLUMN()-2+$F$52),$F$47:$F$51)+SUMPRODUCT(INDEX($C$9:$S$13,,COLUMN()-2+$F$52),$F$47:$F$51)+SUMPRODUCT(INDEX($C$14:$S$18,,COLUMN()-2+$F$52),$F$47:$F$51)} -> 6250 | G23: {=SUMPRODUCT(INDEX($C$4:$S$8,,COLUMN()-2+$F$52),$F$47:$F$51)+SUMPRODUCT(INDEX($C$9:$S$13,,COLUMN()-2+$F$52),$F$47:$F$51)+SUMPRODUCT(INDEX($C$14:$S$18,,COLUMN()-2+$F$52),$F$47:$F$51)} -> 0 | H23: {=SUMPRODUCT(INDEX($C$4:$S$8,,COLUMN()-2+$F$52),$F$47:$F$51)+SUMPRODUCT(INDEX($C$9:$S$13,,COLUMN()-2+$F$52),$F$47:$F$51)+SUMPRODUCT(INDEX($C$14:$S$18,,COLUMN()-2+$F$52),$F$47:$F$51)} -> 6250 | I23: {=SUMPRODUCT(INDEX($C$4:$S$8,,COLUMN()-2+$F$52),$F$47:$F$51)+SUMPRODUCT(INDEX($C$9:$S$13,,COLUMN()-2+$F$52),$F$47:$F$51)+SUMPRODUCT(INDEX($C$14:$S$18,,COLUMN()-2+$F$52),$F$47:$F$51)} -> 0 | J23: {=SUMPRODUCT(INDEX($C$4:$S$8,,COLUMN()-2+$F$52),$F$47:$F$51)+SUMPRODUCT(INDEX($C$9:$S$13,,COLUMN()-2+$F$52),$F$47:$F$51)+SUMPRODUCT(INDEX($C$14:$S$18,,COLUMN()-2+$F$52),$F$47:$F$51)} -> 0 | K23: {=SUMPRODUCT(INDEX($C$4:$S$8,,COLUMN()-2+$F$52),$F$47:$F$51)+SUMPRODUCT(INDEX($C$9:$S$13,,COLUMN()-2+$F$52),$F$47:$F$51)+SUMPRODUCT(INDEX($C$14:$S$18,,COLUMN()-2+$F$52),$F$47:$F$51)} -> 0 | ... S23: {=SUMPRODUCT(INDEX($C$4:$S$8,,COLUMN()-2+$F$52),$F$47:$F$51)+SUMPRODUCT(INDEX($C$9:$S$13,,COLUMN()-2+$F$52),$F$47:$F$51)+SUMPRODUCT(INDEX($C$14:$S$18,,COLUMN()-2+$F$52),$F$47:$F$51)} -> #REF!
C24: R5 | D24: {=SUMPRODUCT(INDEX($C$4:$S$8,,COLUMN()-2+$G$52),$G$47:$G$51)+SUMPRODUCT(INDEX($C$9:$S$13,,COLUMN()-2+$G$52),$G$47:$G$51)+SUMPRODUCT(INDEX($C$14:$S$18,,COLUMN()-2+$G$52),$G$47:$G$51)} -> 0 | E24: {=SUMPRODUCT(INDEX($C$4:$S$8,,COLUMN()-2+$G$52),$G$47:$G$51)+SUMPRODUCT(INDEX($C$9:$S$13,,COLUMN()-2+$G$52),$G$47:$G$51)+SUMPRODUCT(INDEX($C$14:$S$18,,COLUMN()-2+$G$52),$G$47:$G$51)} -> 0 | F24: {=SUMPRODUCT(INDEX($C$4:$S$8,,COLUMN()-2+$G$52),$G$47:$G$51)+SUMPRODUCT(INDEX($C$9:$S$13,,COLUMN()-2+$G$52),$G$47:$G$51)+SUMPRODUCT(INDEX($C$14:$S$18,,COLUMN()-2+$G$52),$G$47:$G$51)} -> 0 | G24: {=SUMPRODUCT(INDEX($C$4:$S$8,,COLUMN()-2+$G$52),$G$47:$G$51)+SUMPRODUCT(INDEX($C$9:$S$13,,COLUMN()-2+$G$52),$G$47:$G$51)+SUMPRODUCT(INDEX($C$14:$S$18,,COLUMN()-2+$G$52),$G$47:$G$51)} -> 0 | H24: {=SUMPRODUCT(INDEX($C$4:$S$8,,COLUMN()-2+$G$52),$G$47:$G$51)+SUMPRODUCT(INDEX($C$9:$S$13,,COLUMN()-2+$G$52),$G$47:$G$51)+SUMPRODUCT(INDEX($C$14:$S$18,,COLUMN()-2+$G$52),$G$47:$G$51)} -> 0 | I24: {=SUMPRODUCT(INDEX($C$4:$S$8,,COLUMN()-2+$G$52),$G$47:$G$51)+SUMPRODUCT(INDEX($C$9:$S$13,,COLUMN()-2+$G$52),$G$47:$G$51)+SUMPRODUCT(INDEX($C$14:$S$18,,COLUMN()-2+$G$52),$G$47:$G$51)} -> 0 | J24: {=SUMPRODUCT(INDEX($C$4:$S$8,,COLUMN()-2+$G$52),$G$47:$G$51)+SUMPRODUCT(INDEX($C$9:$S$13,,COLUMN()-2+$G$52),$G$47:$G$51)+SUMPRODUCT(INDEX($C$14:$S$18,,COLUMN()-2+$G$52),$G$47:$G$51)} -> 0 | K24: {=SUMPRODUCT(INDEX($C$4:$S$8,,COLUMN()-2+$G$52),$G$47:$G$51)+SUMPRODUCT(INDEX($C$9:$S$13,,COLUMN()-2+$G$52),$G$47:$G$51)+SUMPRODUCT(INDEX($C$14:$S$18,,COLUMN()-2+$G$52),$G$47:$G$51)} -> 0 | ... S24: {=SUMPRODUCT(INDEX($C$4:$S$8,,COLUMN()-2+$G$52),$G$47:$G$51)+SUMPRODUCT(INDEX($C$9:$S$13,,COLUMN()-2+$G$52),$G$47:$G$51)+SUMPRODUCT(INDEX($C$14:$S$18,,COLUMN()-2+$G$52),$G$47:$G$51)} -> #REF!
